Workbook

Sheet 00_คู่มือ
A1: คู่มือใช้งานไฟล์ THAI-RAP Excel Template สำหรับกรอกและสรุปข้อมูลร้าน 50 ร้าน
A2: ขั้นตอน | B2: วิธีใช้งาน
A3: 1 | B3: กรอกข้อมูลร้านในชีต 01_ข้อมูลร้าน
A4: 2 | B4: กรอกคะแนน 0-4 ในชีต 02_ประเมิน50ร้าน ช่อง Q1-Q50
A5: 3 | B5: ดูสรุปใน 03_สรุปคะแนน และ 04_Dashboard
A6: 4 | B6: ดูคำถามเต็มและหลักฐานใน 05_QuestionMaster
A7: 5 | B7: Red Flag = ข้อที่ได้คะแนน 0-1
A9: คะแนน | B9: ระดับ | C9: ความหมาย
A10: 0 | B10: ไม่มีเลย | C10: ไม่มีการดำเนินการ/ไม่มีหลักฐาน
A11: 1 | B11: มีบ้าง | C11: ทำบางส่วนแต่ไม่เป็นระบบ
A12: 2 | B12: พื้นฐาน | C12: มีวิธีทำพื้นฐาน
A13: 3 | B13: ดี | C13: เป็นระบบ มีหลักฐาน
A14: 4 | B14: ดีมาก | C14: วัดผลและต่อยอดได้
A16: แหล่งอ้างอิง | B16: รายละเอียด
A17: THAI-RAP_แบบฟอร์มประเมินร้าน_50ข้อ_Manual(3).pdf | B17: ใช้เป็นแบบฟอร์มภาคสนามและรายการประเมิน
A18: THAI-RAP_รายละเอียดแบบประเมินร้าน_50ข้อ_และคู่มือเก็บข้อมูล(2).pdf | B18: ใช้เป็นคู่มือมิติ น้ำหนัก เกณฑ์คะแนน หลักฐาน และ Red Flag

Sheet 01_ข้อมูลร้าน
A1: รหัสร้าน | B1: ชื่อร้าน | C1: จังหวัด | D1: อำเภอ/ตำบล | E1: ประเภทร้าน | F1: เจ้าของ/ผู้ให้ข้อมูล | G1: โทรศัพท์ | H1: ช่องทางขายหลัก | I1: ยอดขายเฉลี่ย/วัน | J1: ยอดขายเฉลี่ย/เดือน | K1: เมนูขายดี 1 | L1: เมนูขายดี 2 | M1: เมนูขายดี 3 | N1: ต้นทุนวัตถุดิบ/เดือน | O1: ค่าแรง/เดือน | P1: ค่าเช่า/ค่าใช้จ่ายประจำ | Q1: กำไรประมาณการ/เดือน | R1: ปัญหาหลัก 3 ข้อ | S1: ด้านสังคม | T1: ด้านสิ่งแวดล้อม | U1: เป้าหมาย 3-6 เดือน | V1: รอบประเมิน | W1: วันที่ประเมิน | X1: ชื่อผู้ประเมิน | Y1: หมายเหตุ
A2: RAP69-001 | B2: Seed restaurant | R2: 1.ร้านมีระบบอยู่ได้ด้วยตัวเอง ( staff training, system, etc.) 2.มี 2 ready-to-products ออกมา ( คง concept วัตถุดิบจากชุมชน ) 3.เพิ่มเมนู สร้างเมนู signature 4.เพิ่มความพร้อมในการให้บริการจนสามารถเปิดดำเนินการได้ทุกวั | S2: ทำอยู่แล้ว supplier (อาหาร) ปัจจุบันเป็นคนในชุมชน 100% + มี consignment นำ product ชุมชนมาวาง แต่ ณ ตอนนี้ยังไม่ได้มีแพลนจะเพิ่มอะไรในด้านนี้ อยากโฟกัสไปกับการวางระบบร้านก่อน | T2: โดยปัจจุบันร้าน concern เรื่องนี้อยู่แล้ว ด้วย concept บรรจุภัณฑ์ถ้า take-away ใช้เป็นกล่องกระดาษ - แก้วกระดาษ ตอนทิ้งขยะมีแยก พลาสติก,ขวดแก้ว, ขยะเปียก (ในชุมชนตรงนั้นมีที่ทิ้งขยะแยกประเภทอย่างละเอียด) | U2: สร้างระบบเทรนนิ่งให้ร้านรันได้ด้วยตัวเองเพื่อความสุขและเวลาชีวิตที่สมดุล ควบคู่การเพิ่มเมนู Signature และคลอด 2 ผลิตภัณฑ์พร้อมทาน โดยมุ่งเน้นการใช้วัตถุดิบและสนับสนุน Supplier ในชุมชน 100% พร้อมคงเจตนารมณ์รักษ์โลกผ่านการแยกขยะและใช้บรรจุภัณฑ์ที่เป็นมิตรต่อสิ่งแวดล้อมอย่างยั่งยืนในปี 2026 | V2: T0
A3: RAP69-002 | B3: ก๋วยเตี๋ยวเรือคุณปุ๊ก | V3: T0
A4: RAP69-003 | B4: บ้าน-บ้าน สุขพอดี | R4: 1.สร้างมาตรฐานการบริการและการประกอบอาหารในแบบฉบับบ้าน-บ้าน สุขพอดี 2.พัฒนาเมนูเด่นจากสวนและเมนูประจำถิ่น เชื่อมโยงการปลูก การปรุง และการเรียนรู้ให้เกื้อหนุนกัน 3.สร้างการรับรู้ให้ผู้คนนึกถึงบ้าน-บ้าน สุขพอดี เมื่อต้องการประสบการณ์ "ดม เด็ด ปรุง จริง" 4.พัฒนาระบบสมาชิกและกิจกรรมต่อเนื่อง เพื่อสร้างการกลับมาเรียนรู้และเติบโตร่วมกัน 5.ยกระดับไซรัปมะพร้าวสู่สินค้าซิกเนเจอร์ ที่สะท้อนคุณค่าจากทรัพยากรและภูมิปัญญาในพื้นที่ | S4: มุ่งเป็นต้นแบบของพื้นที่แห่งอาหาร การเรียนรู้ และการใช้ชีวิตที่เกื้อกูลกัน เชื่อมโยง "สวนสู่ครัว ครัวสู่ชีวิต" ผ่านวัตถุดิบจากธรรมชาติ ภูมิปัญญาท้องถิ่น และประสบการณ์ "ดม เด็ด ปรุง จริง" เพื่อสร้างคุณค่าร่วมทางเศรษฐกิจ สังคม และสิ่งแวดล้อม พร้อมส่งต่อความสุข ความหมาย และความยั่งยืนให้แก่ผู้คน ชุมชน และโลกใบนี้ | U4: ขับเคลื่อนอัตลักษณ์ 'สวนสู่ครัว ครัวสู่ชีวิต' ผ่านมาตรฐานบริการ เมนูถิ่น และประสบการณ์ 'ดม เด็ด ปรุง จริง' ควบคู่การรุกตลาดเพื่อสร้างรายได้รวมในปี 2569 กว่า 900,000 บาท บนฐานคิดการพึ่งพาธรรมชาติและภูมิปัญญาท้องถิ่น มุ่งเป็นต้นแบบพื้นที่อาหารและการเรียนรู้ที่เกื้อกูลสิ่งแวดล้อม พร้อมส่งต่อความสุขและความยั่งยืนให้กับผู้คน ชุมชน และโลกใบนี้ | V4: T0
A5: RAP69-004 | B5: แฟรนไชส์ก๋วยเตี๋ยวปากหม้อแม่ว่าดี | V5: T0
A6: RAP69-005 | B6: 16Brix Melon Farm&Café | R6: 1.เพิ่มยอดขายในส่วนคาเฟ่ ให้มีรายรับเฉลี่ย 250,000 บาทต่อเดือน ที่กำไรสุทธิ 25% โดยมีผลิตภัณฑ์หลักดังนี้ -เมล่อนผล (online&offline) -อาหาร น้ำ -ของฝาก *รวมถึงโอกาสสเกลสาขาเพิ่มยอดขายในสถานที่ที่น่าสนใจ (มองพื้นที่ประเภทกลุ่ม Healthcare) 2.ทำผลิตภัณฑ์ที่มีโอกาสเข้าสู่ตลาดใหญ่ได้ และเสกลได้ เพื่อเพิ่มรายรับแบบก้าวกระโดด (หลักล้านบาท) - ก้านไม้หอม กลิ่นเมล่อน (มีสินค้าแล้ว ผลิตโดย วว. ขายทาง online&offline อยู่) - แยมเมล่อน (ทดลองขาย offline อยู่ แต่อยากได้เทคโนโลยียืดอายุ) - Melon Apply Cyder เปลือกเมล่อนลอยแก้ว (ต้นทุนต่ำเนื่องจากเป็น Byproduct ทดลองขายอยู่ แต่อยากพัฒนาแพคเกจ และเทคนิคการยืดอายุ 3.เพิ่มการรับรู้แบรนด์ และเปลี่ยน traffic เป็น income ไปสู่เป้าหมายข้อ 1&2 4.เซทระบบให้งานทุกส่วนรันได้แม้ไม่มีตัวเจ้าของอยู่ | S6: ทางสังคมเรามีการใช้วัตถุดิบในพื้นที่ - เมล่อนปลูกเอง - แรงงานท้องถิ่น - เมล็ดกาแฟ แป้งพิซซ๋า จากกลุ่ม YEC นครนายก - ผักสลัดจากฟาร์มใกล้เคียง | T6: ด้านสิ่งแวดล้อม - ทางฟาร์มใช้โซล่าเซลในส่วนการปลูก - ออกแบบเมนูจาก Byproduct เช่นเปลือกทำลอยแก้ว ผิวเปลือกมีส่งให้น้องที่ม.ศีรนครินทำวิจัย | U6: เซ็ตระบบคาเฟ่ให้รันอัตโนมัติเพื่อยอดขาย 250,000 บาทต่อเดือน ควบคู่การปั้นและยืดอายุผลิตภัณฑ์เมล่อนนวัตกรรมสู่ตลาดใหญ่ในปี 2026 บนฐานความยั่งยืนที่ใช้พลังงานโซล่าเซลล์และขับเคลื่อนครัวแบบไร้ขยะด้วยการแปรรูป Byproduct พร้อมเกื้อกูลสังคมผ่านการจ้างงานและกระจายรายได้สู่เครือข่ายเกษตรกรท้องถิ่นอย่างมั่นคง | V6: T0
A7: RAP69-006 | B7: ร้านอีสานเฮาส์ (304 ปราจีนบุรี) | R7: เป้าหมายทางธุรกิจ : เพิ่มยอดขายให้ได้เดือนละ 5 ล้านบาทต่อเดือน โดยทำร้านให้เป็นห้องรับแขกของจังหวัดปราจีนบุรีให้ได้ - เป็นแลนด์มาร์กของปราจีนบุรี - เป็นร้านที่บริษัท โรงงานต่างๆ และหน่วยงานราชการ เลือกใช้การจัดเลี้ยง ประชุม สัมมนา - เป็นร้านที่คนในพื้นที่อยากพาครอบครัวมาทานอาหารหรือเลี้ยงฉลองในวันสำคัญ - เป็นร้านที่ต้องแวะสำหรับคนที่เดินทางผ่านถนน 304 | S7: เป้าหมายทางสังคม : ร้านอีสานเฮาส์จะเป็นร้านที่ทำให้คนปราจีนบุรีภูมิใจ โดยสร้างงานให้คนในท้องถิ่นได้มีอาชีพ - มีรับนักศึกษาฝึกงานมาฝึกทำอาหารและสร้างเส้นทางความก้าวหน้าในอาชีพ - มีการสนับสนุนเกษตรกรในท้องถิ่น และซื้อวัตถุดิบจากชุมชน ให้ชาวบ้านมีรายได้ เช่น หน่อไม้ไผ่ตง, กุ้งฝอยจากชาวบ้านที่หามาจากแม่น้ำปราจีนบุรี, ปูนาจากชาวบ้านที่ไปขุดจากทุ่งนา เพื่อทำให้ร้านอีสานเฮาส์ไม่ใช่แค่ร้านอาหาร แต่เป็นส่วนหนึ่งของคนจังหวัดปราจีนบุรี | T7: ป้าหมายด้านสิ่งแวดล้อม : ต้องการลดขยะอาหาร และสามารถนำขยะที่เหลือไปใช้ประโยชน์ต่อได้ เช่น ชาวบ้านนำไปเลี้ยงสัตว์ หรือแปรรูปให้เป็นปุ๋ยต่อไป - ส่งเสริมให้ลูกค้านำภาชนะมาใส่เครื่องดื่มเอง แล้วลดราคาเครื่องดื่ม (ตอนนี้ทำอยู่) - สร้างพื้นที่สีเขียว โดยปลูกสวนสมุนไพร ใช้พื้นที่ร้านเป็นแหล่งเรียนรู้เล็กๆ | U7: ปั้นอีสานเฮาส์สู่ห้องรับแขกและแลนด์มาร์กของปราจีนบุรีเพื่อสร้างยอดขาย 5 ล้านบาทต่อเดือน บนฐานความสุขที่เจ้าของร้านมีระบบบริหารจนมีเวลาให้ครอบครัวและพนักงานเติบโตอย่างมั่นคง ควบคู่การสร้างงาน อุดหนุนวัตถุดิบชุมชนอย่างหน่อไม้ไผ่ตงและกุ้งฝอย ตลอดจนจัดการขยะอาหารเพื่อเลี้ยงสัตว์ ทำปุ๋ย และเพิ่มพื้นที่สีเขียวอย่างยั่งยืน | V7: T0
A8: RAP69-007 | B8: ร้านคำนิยม | R8: 5 เป้าหมาย ปี 2569 1.เพิ่มยอดขายรวม 30% 2.พัฒนาระบบมาตรฐานร้านอาหาร (SOP) ครบ 100% 3.ลดต้นทุนอาหาร (FOOD COST) ให้ต่ำกว่า 35% 4.สร้างฐานลูกค้าประจำ 1,000 คน 5.ยกระดับแบรนด์ "คำนิยม" ให้เป็นอาหารที่รับจัดเลี้ยงในและนอกสถานที่ อันดับต้นในพื้นที่ | S8: ใช้ผักและวัตถุดิบท้องถิ่นจากชาวบ้านในพื้นที่เพิ่มขึ้น โดยเฉพาะวัตถุดิบตามฤดูกาล | T8: แยกขยะโดยเฉพาะขยะเศษอาหาร ให้สามารถนำไปทำปุ๋ยหรือใช้เป็นอาหารสัตว์ได้ | U8: พุ่งเป้าเพิ่มยอดขายรวม 30% และลด Food Cost ให้ต่ำกว่า 35% ควบคู่การวางระบบ SOP ครบ 100% เพื่อยกระดับแบรนด์ 'คำนิยม' สู่อันดับต้นของธุรกิจจัดเลี้ยงในปี 2569 บนฐานความสุขที่เจ้าของร้านมีเวลาชีวิตที่สมดุลและพนักงานเติบโตอย่างมีพลัง พร้อมสร้างคุณค่าร่วมกับชุมชนผ่านการใช้ผักและวัตถุดิบตามฤดูกาลในพื้นที่ และจัดการแยกขยะเศษอาหารเพื่อหมุนเวียนประโยชน์กลับสู่สิ่งแวดล้อมอย่างยั่งยืน | V8: T0
A9: RAP69-008 | B9: ร้านอรวรรณบ้านเพ | V9: T0
A10: RAP69-009 | B10: ครัวเดอมอง | V10: T0
A11: RAP69-010 | B11: เรือนไทย พัทยา | V11: T0
A12: RAP69-011 | B12: ร้านอาหาร ทะเลลานโพธิ์ ซีฟู้ด | S12: ผลักดันซีฟู้ดท้องถิ่นกลุ่มหมู่บ้านชาวประมง พ่อค้าเเม่ค้า เมืองพัทยา จังหวัดชลบุรี ออกสู่ตลาดระดับประเทศเเละต่างประเทศให้เป็นที่รู้จัก และดึงดูดนักท่องเที่ยวทั้งชาวไทย เเละชาวต่างชาติ เข้ามาในชุมชน สร้างความเจริญและสร้างรายได้สู่ชุมชน เเละเมืองพัทยา | U12: ยกระดับซีฟู้ดพัทยาสู่แบรนด์ของฝากพรีเมียมด้วยนวัตกรรมและระบบ SOP เพื่อโตรายได้ 25% ปี 2569 บนฐานความสุขที่ได้ส่งมอบความปลอดภัยจนลูกค้ากลายเป็นเพื่อน ควบคู่การลดขยะวัตถุดิบ 10% และผลักดันผลผลิตประมงพื้นบ้านสู่สากลเพื่อสร้างรายได้กลับคืนสู่ชุมชนอย่างยั่งยืน | V12: T0
A13: RAP69-012 | B13: นายกุ่ยไก่หุบบอน @เขาชีจรรย์ | R13: 1. การขยายสาขาเพิ่มการเติบโต 2. เพิ่มเทคโนโลยีเข้ามามีส่วนร่วมในการจัดการ 3. การเพิ่มช่องทางรายได้ใหม่ 4. การจัดการต้นทุน | S13: นำไก่หุบบอน ไก่พื้นเมืองชลบุรี ออกสู่ตลาดระดับประเทศ ให้เป็นที่รู้จัก และดึงดูดนักท่องเที่ยว เข้ามาในชุมชน สร้างความเจริญและสร้างรายได้สู่ชุมชน | U13: สปีดการเติบโตด้วยสาขาพัทยา ระบบแฟรนไชส์ และไก่สับแช่แข็งบุกโมเดิร์นเทรดด้วยระบบ SOP คุมต้นทุนปี 2569 บนฐานความสุขที่ได้ทำสิ่งที่รักและส่งมอบความอร่อยสะอาดจนลูกค้ากลายเป็นเพื่อน ควบคู่การผลักดันไก่พื้นเมืองชลบุรีสู่ระดับประเทศเพื่อดึงดูดนักท่องเที่ยวและสร้างรายได้กลับคืนสู่ชุมชน | V13: T0
A14: RAP69-013 | B14: บ้านสวนบางแสน | V14: T0
A15: RAP69-014 | B15: สวนแววอรุณ | R15: หลังจากกลับมาจากงาน THAI-RAP ผมมาวิเคระห์สถานการณ์เศรษฐกิจ เลยสรุปว่าปีนี้เราจะไม่โฟกัสการไล่ยอดขายครับ แต่จะโฟกัสการสร้างระบบ เพราะเมื่อระบบแข็งแรง ยอดขายจะเป็นผลลัพธ์ที่ตามมาเองเป้าหมายสำคัญของสวนแววอรุณในปี 2569 คือ การจัดทำ SOP ให้ครบทุกแผนก เพื่อเปลี่ยนการทำงานที่พึ่งพาประสบการณ์ของแต่ละคน ให้กลายเป็นมาตรฐานขององค์กร โดยครอบคลุม SOP การจัดเตรียมวัตถุดิบ SOP การปรุงอาหารและมาตรฐานสูตรอาหาร SOP ร้านอาหารและการบริการลูกค้า SOP คาเฟ่และเครื่องดื่ม SOP ที่พัก SOP ลานกางเต็นท์ SOP กิจกรรมและความปลอดภัย SOP การตลาดและการสื่อสารกับลูกค้า SOP งานบริหารและการควบคุมต้นทุน เป้าหมายของเราไม่ใช่เพียงทำให้พนักงานทำงานตามขั้นตอน แต่เพื่อสร้างองค์กรที่สามารถรักษาคุณภาพ มาตรฐาน และประสบการณ์ของลูกค้าได้อย่างสม่ำเสมอ | S15: ด้านสังคม เราให้พื้นที่ชุมชน เข้ามาใช้พื้นที่ของเราจัดกิจกรรมมากขึ้น เช่น เราให้.ศกร.ใช้พื้นที่ตั้งห้องสมุดชุมชน มุมหนังสือประชาชน | T15: ด้านสิ่งแวดล้อม - รักษาพื้นที่สีเขียวและระบบนิเวศภายในสวน และมีการขยายการปลูกต้นไม้และพันธุ์ไม้ป่าในพื้นที่อีก 10 ไร่ - เพิ่มการใช้วัสดุที่เป็นมิตรต่อสิ่งแวดล้อม - พัฒนาระบบจัดการขยะและเศษอาหารให้เกิดประโยชน์สูงสุด โดยปัจจุบัน เราร่วมกับทีมงานวิจัยที่นำเศษอาหารไปทำเป็นอาหารเลี้ยงหนอนเพื่อใช้เป็นแหล่งโปรตีนสัตว์ทดแทนการนำเข้าถั่วเหลืองเป็นต้น - ในช่วงต้นปีที่ผ่านมา เราเพิ่งติดตั้งพลังงานแสงอาทิตย์เพื่อใช้เป็นพลังงานสะอาด | U15: สร้างระบบ SOP ครบทุกแผนกเพื่อยกระดับมาตรฐานบริการและประสบการณ์ของลูกค้าอย่างสม่ำเสมอโดยไม่พึ่งพาบุคคลในปี 2569 บนฐานคิดการเติบโตอย่างมีสติที่โฟกัสระบบก่อนยอดขาย ควบคู่การขยายพื้นที่ป่าสีเขียว 10 ไร่ ใช้พลังงานแสงอาทิตย์ และจัดการขยะเศษอาหารสู่นวัตกรรมอาหารหนอนโปรตีนเพื่อสิ่งแวดล้อม พร้อมเปิดพื้นที่สร้างคุณค่าให้สังคมด้วยการเป็นแหล่งเรียนรู้และห้องสมุดสำหรับชุมชนอย่างยั่งยืน | V15: T0
A16: RAP69-015 | B16: คุณอี๊ดกะเพราแซ่บจี้ด | V16: T0
A17: RAP69-016 | B17: หมูสะเต๊ะอพอลโล | V17: T0
A18: RAP69-017 | B18: วันวาน คาเฟ่ | V18: T0
A19: RAP69-018 | B19: อิ่มอุ่น ณ พัทยา | R19: 1.จัดการระบบ ของพัทยา เพื่อเตรียมขยายสาขาไปกทม. 2.ทำระบบสมาชิก เพื่อให้ลูกค้าเก่ามาใช้บริการซ้ำ/ ให้ระบบหลังบ้านรับทราบข้อมูล ไม่ใช่เพียงจำหน้าลูกค้าได้ 3.ปรับทัศนคติ น้องบริการ ให้ยิ้มเเย้วและกล่าวต้อนรับ-ขอบคุณลูกค้า 4. ทำมุมเช็คอิน 5. จัดทำผลิตภัณเเช่เเข็งเสี่ยวหลงเปา(จากเมนูที่ติดลำดับขายดี) ให้ลูกค้าซื้อกลับ 6. ทำระบบให้ลูกคอมเพลน ผ่าน google form เพื่อเปิดฟังความคิดเห็นลูกค้ามากขึ้น | S19: 1.ทางร้านสนับสนุน ของใช้พื้นบ้านจักรสาร ที่ใช้ตกแต่งร้านจากชุมชน ในจังหวัดชลบุรร 2.การสนับสนุนประมงพื้นบ้าน ทางร้านใช้วัสดุดิบอาหารทะเลในท้องถิ่น | T19: 1.ทำระบบ SOP ล็อกมาตรฐานเมนูเด็ดและควบคุม Food Cost ช่วยลดขยะที่เกิดจากอาหารเหลือทิ้ง 2.สำหรับสินค้าแช่แข็ง ในแผนการพัฒนาผเสี่ยวหลงเปาแช่แข็ง เราจะศึกษาและเลือกใช้บรรจุภัณฑ์ | U19: จัดระบบสาขาของพัทยารองรับการขยายสาขาสู่ กทม. ทำระบบสมาชิก และปั้นเสี่ยวหลงเปาแช่แข็งปี 2026 บนฐานความสุขที่เห็นแบรนด์อิ่มอุ่นเติบโตต่อเนื่องและสร้างความอร่อยให้ทุกครอบครัว ควบคู่การลดขยะอาหารด้วย SOP คุมต้นทุน ตลอดจนอุดหนุนงานจักสานและใช้วัตถุดิบซีฟู้ดจากประมงพื้นบ้านชลบุรีเพื่อขับเคลื่อนเศรษฐกิจชุมชน | V19: T0
A20: RAP69-019 | B20: ร้านอาหารบ่อทองบุรี | R20: 1. แผนยกระดับมาตรฐานการบริการ และอัตลักษณ์อาหาร เป้าหมาย : จัดทำเล่มเมนูใหม่ที่รองรับกลุ่มลูกค้าต่างชาติ ควบคู่ไปกับการพัฒนาศิลปะการจัดจาน เพื่อเพิ่มมูลค่าและความน่าสนใจให้แก่อาหาร แนวทางการดำเนินงาน : ออกแบบและจัดทำเล่มเมนูใหม่ 3 ภาษา (ไทย, อังกฤษ, จีน) เพื่อให้ครอบคลุมและตอบโจทย์การบริการอย่างเป็นสากล คัดเลือกและปรับปรุงภาชนะใส่อาหารชุดใหม่ ให้มีความสวยงามและเข้ากับอัตลักษณ์ของแต่ละเมนู กรอบเวลา : ดำเนินการควบคู่กันให้แล้วเสร็จภายใน 3 เดือน กันยายน 2569 2. แผนพัฒนาประสิทธิภาพระบบครัวและการบริหารจัดการ เป้าหมาย: พัฒนาทักษะบุคลากรและจัดวางระบบบริหารจัดการวัตถุดิบภายในครัวเพื่อลดความสูญเสีย (Food Waste) และเตรียมความพร้อมรองรับฤดูกาลท่องเที่ยวแนวทางการดำเนินงาน : จัดอบรมและพัฒนาทักษะการบริหารจัดการครัว การควบคุมมาตรฐานรสชาติ และการจัดการสต็อกวัตถุดิบอย่างเป็นระบบ กรอบเวลา : ดำเนินการในช่วง กรกฏาคมสิงหาคม 2569 เลือกช่วง Low Season ที่ปริมาณงานหน้าร้านลดลง เพื่อให้บุคลากรโฟกัสกับการพัฒนาได้อย่างเต็มที่ 3. แผนพัฒนาผลิตภัณฑ์นวัตกรรมอาหารและมาตรฐาน อย. เป้าหมาย : พัฒนา "พริกแกงปรุงสำเร็จ" สู่การเป็นของฝากระดับพรีเมี่ยมที่ตอบโจทย์เทรนด์คนรักสุขภาพ พร้อมยกระดับโรงเรือนผลิตให้ผ่านการรับรองมาตรฐาน อย. แนวทางการดำเนินงาน ด้านตัวผลิตภัณฑ์ : ปรับสูตรพริกแกงสำเร็จรูปให้เป็นทางเลือกเพื่อสุขภาพ เช่น การลดโซเดียม ลดน้ำตาล หรือใช้สิ่งทดแทนเพื่อสุขภาพ โดยยังคงรักษาอัตลักษณ์ รสชาติ และสีสันดั้งเดิมของอาหารไทยไว้ ด้านบรรจุภัณฑ์ : พัฒนา Packaging ใหม่ให้มีความสวยงาม ดึงดูดสายตา และสะท้อนคุณค่าความเป็นของฝากพรีเมี่ยมด้านมาตรฐานการผลิต : ดำเนินการจัดตั้งโรงเรือนผลิต (ปัจจุบันโครงสร้างอาคารเสร็จสมบูรณ์แล้ว) โดยจะติดตั้งเครื่องผัด เครื่องบรรจุ และระบบที่เกี่ยวข้อง พร้อมยื่นเอกสารตรวจประเมินเพื่อรับรองมาตรฐาน อย. กรอบเวลา : ดำเนินการติดตั้งระบบโรงเรือนและยื่นตรวจประเมิน อย. ให้แล้วเสร็จภายใน ตุลาคม - พฤษจิกายน 2026 ขึ้นอยู่กับการอนุมัตของ อย. | S20: 1.ปล่อยปลาประจำเดือน ที่อ่างเก็บน้ำคลองหลวงรัชโลทร 2.ถวายภัตรตราหารพระประจำเดือน 3.การมอบข้าวสาร และเลี้ยงอาหารกลางวันเด็ก ประจำ 4.กิจกรรมผูกเสี่ยว ดำนา เกี่ยวข้าว ประจำทุกปี 5.กิจกรรมปลูกป่าชุมชนเพื่อการเรียนรู้ ประจำทุกปี 6.กิจกรรมวันสงกรานต์ รดน้ำขอพรผู้ใหญ่ การกวนข้าวเหนียวแดง ประจำทุกปี 7..สนับสนุนกิจกรรมของชุมชน อำเภอ ทุกงาน ไม่ว่าจะเป็น งานบุญกลางบ้าน งานแม่ศรีผีกระดง งานพ่อพญาเร่ งานประกวดสาวงาม 8.มีศูนย์โอทอป สนับสนุนพื้นที่และพนักงานขายให้ฟรี 9.การประชุมสัมมนาและงานแต่ง จะใช้เบรคเป็นขนมจากภายในชุมชน เป็นขนมไทย ขนมพื้นบ้าน | U20: ยกระดับเมนูและศิลปะการจัดจานสู่สากล ควบคู่กับการเป็นครัวไร้ขยะ (Zero Food Waste) และพัฒนาพริกแกงเพื่อสุขภาพมาตรฐาน อย. โดยร้อยเรียงวัตถุดิบและภูมิปัญญาท้องถิ่นเพื่อกระจายรายได้สู่ชุมชนบ่อทอง พร้อมรับไฮซีซั่นปี 2026 บนฐานความสุขและทีมงานที่มีพลังชีวิตที่สมดุล | V20: T0
A21: RAP69-020 | B21: ผัดไทยคาเฟ่แม่วรรณา | R21: เป้าหมาย: ⁃ ทำให้คนรู้จักแบรนด์และร้านผัดไทยคาเฟ่แม่วรรณาเพิ่มมากขึ้น 70 % ⁃ พัฒนาผัดไทยให้มีรสชาติที่เป็นเอกลักษณ์ (Signature) โดยใช้ "น้ำซอสผัดไทยแม่วรรณา" เป็นหัวใจสำคัญ เพื่อให้ลูกค้าไม่ว่าจะทานเมื่อไหร่หรือที่ไหนก็จะได้รสชาติและคุณภาพที่คงที่ ด้วยการรักษามาตรฐานของร้านเป็นสำคัญ ⁃ มียอดขายเพิ่ม 10,000 - 15,000 บาทต่อวัน ⁃ พัฒนาและเรียนรู้สร้างช่องทางออนไลน์ (Facebook, TikTok, Google Maps) ให้มีผู้ติดตามเพิ่มขึ้นอย่างต่อเนื่อง ⁃ ขยายสาขา และพัฒนารูปแบบ Food Truck และ Franchise ให้โดดเด่นทันสมัยเป็นที่น่าสนใจและน่าลงทุน ⁃ เพิ่มช่องทางกิจกรรมเหมาเสิร์ฟ จัดเลี้ยง Catering และออกงานEvent ต่างๆมากขึ้น ⁃ พัฒนาผลิตภัณฑ์เป็นของฝาก เช่น ซอสผัดไทย ผัดไทยพร้อมทาน และผัดไทยกึ่งสำเร็จรูป แบรนด์แม่วรรณา ให้มีคุณภาพมาตรฐานอย.และปลอดภัย รสชาติเหมือนทานที่ร้าน ⁃ พัฒนาซอสผัดไทย ให้มีสูตรต่างๆนอกจากสูตร ดั้งเดิม แม่วรรณา เป็นสูตรซอสผัดไทยรสสละ และสูตรซอสผัดไทยรสสับปะรด โดยใช้วัตถุดิบในท้องถิ่นที่ขึ้นชื่อมีเอกลักษ์ที่โดดเด่นและแตกต่างเป็นหลัก ⁃ ยกระดับจากร้านอาหารสู่ระบบมาตรฐาน (SOP): การจัดทำขั้นตอนการทำ (SOP) ที่ชัดเจน เพื่อให้การขยายสาขาหรือการบริหารจัดการฟู้ดทรัคเป็นไปได้อย่างมีประสิทธิภาพ ลดความผิดพลาด และควบคุมต้นทุน ⁃ ปรับภาพลักษณ์ผัดไทยจากอาหารริมทาง (Street Food) ให้มีความเป็นไลฟ์สไตล์มากขึ้น ทั้งการตกแต่งรถเทลเลอร์ฟู้ดทรีคให้โดดเด่นเป็นที่จดจำ และแตกต่างมีมุมที่น่าถ่ายรูป ⁃ สร้างเพลงประจำร้านทำให้ลูกค้าจดจำ แบรนด์ ฟังแล้วติดหูเพื่อเข้าถึงกลุ่มลูกค้าได้ง่าย ⁃ มีที่ปรึกษาแหล่งเงินทุน เพื่อโอกาสขยายธุรกิจ ⁃ เป้าหมายสูงสุด: เพื่อให้ "ผัดไทยคาเฟ่แม่วรรณา" ไม่ใช่เป็นมากกว่าร้านอาหาร (Street Food)แต่เป็น "แบรนด์ผัดไทยระดับสากล" ที่มีระบบการจัดการหลังบ้านที่แข็งแกร่ง มีภาพลักษณ์ที่ทันสมัย และเป็นที่จดจำทั้งในแง่ของรสชาติและประสบการณ์ เป็นที่รู้จักทั้งชาวไทยและชาวต่างชาติ | S21: ร้านผัดไทยคาเฟ่แม่วรรณามุ่งสร้างคุณค่าทั้งทางเศรษฐกิจ สังคม และสิ่งแวดล้อม โดยสนับสนุนชุมชนท้องถิ่น ใช้ทรัพยากรอย่างรับผิดชอบ และมีคุณค่า สร้างความสุขให้แก่ลูกค้า พนักงาน ตัวเราและผู้มีส่วนเกี่ยวข้องทุกฝ่าย. | U21: ทะยานสู่ยอดขายเพิ่ม 15,000 บาทต่อวันด้วยซอสผัดไทยสูตรผลไม้ท้องถิ่นและของฝากมาตรฐาน อย. พร้อมวางระบบ SOP พลิกโฉมสู่ Food Truck ทันสมัยเพื่อขยายแฟรนไชส์สู่สากลในปี 2026 บนฐานความสุขของตัวเรา ทีมงาน และลูกค้า ผ่านการสนับสนุนวัตถุดิบชุมชนอย่างเกื้อกูล และใช้ทรัพยากรอย่างรับผิดชอบต่อสิ่งแวดล้อมในทุกขั้นตอน | V21: T0
A22: RAP69-021 | B22: Recharge Cafa | V22: T0
A23: RAP69-022 | B23: หมึกสดริมเล | R23: เป้าหมายของร้านหมึกสดริมเลในปีนี้ 1มีระบบหลังบ้านที่แข็งแรง SOP พนักงาน รวมไปถึงระบบสูตรอาหารคำนวณต้นทุน , Stock , ต้องทำให้ครบทุกเมนูในปีนี้ และปีนี้ระบบหลังบ้านจะต้องแข็งแรงที่สุดในรอบ 5 ปี ตั้งแต่เปิดมา 2.รักษายอดขายให้ได้ 1.5 ล้าน / เดือน หรือทำยอดขายให้มากขึ้นกว่านั้น 3.สร้างตัวตนในโลกออนไลน์การตลาดออนไลน์ให้มากกว่านี้ 4.ขยาย หมึกสดริมเล โมเดลเล็กๆไป บางแสนให้ได้ | S23: ช่วยส่งเสริมให้ชาวประมง คนเรือ ให้มีรายได้มากขึ้นและมั่นคงกว่าเดิม | U23: ปฏิวัติระบบหลังบ้านและสูตรอาหารให้แข็งแกร่งที่สุดในรอบ 5 ปี ควบคู่การรุกตลาดออนไลน์และขยายสาขาโมเดลเล็กที่บางแสนเพื่อสร้างยอดขายเสถียรเกิน 1.5 ล้านบาทต่อเดือน โดยยืนหยัดส่งมอบอาหารทะเลที่สดใหม่ แปลกใหม่ และอร่อย บนฐานการจับมือร่วมกับชาวประมงและคนเรือท้องถิ่นเพื่อสร้างรายได้ที่มั่นคงและเกื้อกูลวิถีชุมชนริมเลอย่างยั่งยืนในปี 2026 | V23: T0
A24: RAP69-023 | B24: บ้านแมะคาเฟ่ | R24: เป้าหมายในปี2026 เป็นจุดหมายปลายทางของนักท่องเที่ยวที่มาเที่ยวจันทบุรี * ติด Top คาเฟ่ที่นักท่องเที่ยวค้นหาในจันทบุรี * มีลูกค้าใหม่จากนักท่องเที่ยวไม่น้อยกว่า 50% * สร้างประสบการณ์ “จากเกษตรกรถึงลูกค้าโดยตรง“ พัฒนาสินค้าแบรนด์บ้านแมะ ให้จัดเจนและเข้มแข็งมากขึ้น เพื่อการขยายสาขา สร้างระบบร้านให้ทำงานได้แม้เจ้าของไม่อยู่ * มีหัวหน้าทีมแต่ละแผนก * จัดทำระบบ SOP ให้ชัดเจนยิ่งขึ้น * ลดปัญหางานตกหล่น * เจ้าของสามารถออกไปพัฒนาธุรกิจได้มากขึ้น พัฒนาทีมงาน * จัดอบรมพนักงาน สร้างทีมงานที่มีทักษะ เก่ง เพื่อการเป็นมืออาชีพ | S24: - เราสนับสนุนและรับซื้อผลผลิตจากเกษตรกรในพื้นที่เพื่อสร้างรายได้หมุนเวียนในชุมชน - สนับสนุนทุนการศึกษา ด้านกีฬา นักเรียนเรียนดี ของโรงเรียนในชุมชน (โรงเรียนบ้านเนินดินแดง / โรงเรียนมัธยมวัดเขาสุกิม) - ให้การสนับสนุนการมีงานทำ ของนักเรียนในชุมชน ให้มีอาชีพเสริม หลังจากเลิกเรียนหรือวันหยุด และเรารองรับการมีงานทำ ของนักเรียนที่มีความประสงค์เรียนจบแล้ว อยากมีงานทำเลย - สนับสนุนโรงทาน เลี้ยงโรงทาน ของทางวัดประจำจังหวัดในชุมชน เวลามีงานหรือเทศกาลต่างๆ | T24: ด้านสิ่งแวดล้อม - ทางร้านมีการคัดแยกขยะก่อนนำไปทิ้ง และแยกขยะสิ่งไหนเก็บไว้ขายต่อได้ - เศษอาหาร ทางร้านได้นำไปให้เป็นอาหารสัตว์ เลี้ยงปลา เลี้ยงไก่ - กากกาแฟทางร้านได้นำไปตากแล้วทำเป็นปุ๋ย ใส่ต้นไม้ แปลงผัก และแปลงดอกไม้ของทางร้าน | U24: ปั้นบ้านแมะสู่ Top คาเฟ่จันทบุรีด้วยระบบ SOP ที่พร้อมขยายสาขาปี 2026 ควบคู่การสร้างงานและมอบทุนการศึกษาแก่เยาวชน พร้อมจัดการขยะหมุนเวียนในร้าน เพื่อความสุขของทีมงานและการมีเวลาให้ครอบครัวอย่างยั่งยืน | V24: T0
A25: RAP69-024 | B25: ร้านทองม้วนคุณใบ้ | R25: ป้าหมายปีนี้ 2026 1.จัดทำคู่มือในการทำขนมทองม้วน 2.จัดระบบการทำงานในร้านทั้งหน้าร้าน และหลังร้าน 3.จัดหาระบบ POS ที่ช่วยจัดการการขาย,บัญชี,สต๊อกวัตถุดิบและสินค้า 4.เพิ่มร้านค้าพันธมิตรเพื่อรับขนมทองม้วนไปขายต่อ (B2B) 5.พัฒนาขนมทองม้วนรสชาติใหม่ | S25: ยกระดับระบบปฏิบัติการภายในร้าน พัฒนาทองม้วนรสชาติใหม่ ขยายตลาดออนไลน์ และ B2B สนับสนุนวัตถุดิบท้องถิ่น สืบทอดภูมิปัญญาขนมไทย และลดผลกระทบต่อสิ่งแวดล้อมในการดำเนินธุรกิจ | U25: ยกระดับระบบปฏิบัติการภายในร้านเพื่อเพิ่มประสิทธิภาพการทำงานอย่างเป็นระบบ ควบคู่การขยายตลาดออนไลน์ B2B และพัฒนาทองม้วนรสชาติใหม่เพื่อเพิ่มยอดขายในปี 2026 บนฐานความยั่งยืนร่วมกับท้องถิ่น ด้วยการสนับสนุนวัตถุดิบชุมชนและสืบทอดภูมิปัญญาขนมไทยอันทรงคุณค่า พร้อมใส่ใจสิ่งแวดล้อมด้วยการลดผลกระทบจากการดำเนินธุรกิจในทุกขั้นตอน | V25: T0
A26: RAP69-025 | B26: ร้านไชโย | V26: T0
A27: RAP69-026 | B27: ก๋วยเตี๋ยวปากหม้อ เกวียนนิยม | V27: T0
A28: RAP69-027 | B28: Chatrium Golf Resort Soidao | V28: T0
A29: RAP69-028 | B29: มาเว้า MA WAO | V29: T0
A30: RAP69-029 | B30: ร้านต้นสลัด | V30: T0
A31: RAP69-030 | B31: The Sunset Deck | V31: T0
A32: RAP69-031 | B32: ร้านครัวรวมรส ๒๕๖๔ จังหวัดตราด | R32: ทำการตลาดให้ลูกค้ารู้จักร้านให้มากขึ้น เน้นพัฒนาสูตรอาหารและระบบหลังร้านใหมีประสิทธิภาพมากที่สุด เพื่อที่จะได้มีเวลาไปจัดการเรื่องอื่นโดยไม่ต้องคอยเฝ้าร้าน และลงมือทำเองทุกอย่างในร้าน | V32: T0
A33: RAP69-032 | B33: ร้านคดข้าว | R33: เป้าหมาย ของร้านคดข้าว 5 ข้อ 1.ต้องการพัฒนา แบรนด์และสานต่อระบบ SOP ที่ดีเยี่ยม 2.ต้องการพัฒนาผลิตภัณฑ์ และต่อยอด ธุรกิตเฟรนไซน์ 3.พัฒนาและ สารต่ออัตลักษณ์ของอาหารพื้นถิ่นจันท์ 4.พัฒนาแรงงานและสร้างมาตรฐานการบริการที่ดีเยี่ยม 5. สร้างแบรนด์ ให้ เป็น ที่จดจำและเป็นแบบอย่าง ในระดับประเทศ | S33: ร้านคดข้าวมุ่งมั่นเติบโตไปพร้อมกับท้องถิ่น โดย เกษตรกรจันทบุรีจะได้รับรายได้ที่มั่นคงและเป็นธรรม (Fair Trade) จากการที่ร้านเข้าทำสัญญาซื้อขายวัตถุดิบอัตลักษณ์เมืองจันท์โดยตรง (Contract Farming) ไม่ผ่านคนกลาง ทั้งกลุ่มผลไม้ตามฤดูกาลและพืชสมุนไพรพื้นบ้าน ทำให้ชาวสวนมีตลาดรองรับผลผลิตที่แน่นอนในราคาที่เหมาะสม ส่วน ชุมชนจะได้รับการยกระดับเศรษฐกิจและการท่องเที่ยว ผ่านการชูภูมิปัญญา 'รสมือยาย' และวัตถุดิบท้องถิ่นมาสร้างมูลค่าเพิ่มเป็นผลิตภัณฑ์สร้างชื่อให้จังหวัด พร้อมกันนี้ ชุมชนยังจะได้รับประโยชน์จากแนวคิดความยั่งยืนที่ร้านนำระบบ SOP มาบริหารจัดการขยะอาหาร (Zero Waste) เพื่อลดผลกระทบต่อสิ่งแวดล้อม และสร้างโมเดลธุรกิจต้นแบบที่เป็นมิตรต่อชุมชนอย่างแท้จริง | U33: ยกระดับระบบ SOP และมาตรฐานบริการเพื่อรักษาคุณค่ารสชาติเก่าเล่าด้วยใจสู่อินเตอร์ ควบคู่การวางระบบครัวกลางและพัฒนาผลิตภัณฑ์พร้อมสเกลขยายสาขาทั่วประเทศในปี 2026 บนฐานความยั่งยืนร่วมกับท้องถิ่น ด้วยการทำข้อตกลงกับกลุ่มเกษตรกรเมืองจันท์เพื่อสร้างรายได้ที่เป็นธรรม (Fair Trade) ควบคู่กับการสืบสานภูมิปัญญาอาหารพื้นถิ่น และบริหารจัดการขยะอาหารในร้านเป็นศูนย์ (Zero Waste) เพื่อเป็นโมเดลธุรกิจต้นแบบที่สร้างความสุขให้ทั้งชุมชนและผู้บริโภค | V33: T0
A34: RAP69-033 | B34: GRID GARDEN | R34: เป้าหมายในปีนี้ของร้าน "Grid Garden" มุ่งมั่นพัฒนาพื้นที่แห่งความสุขของครอบครัวให้มีระบบการจัดการที่สมบูรณ์ โดยการ จัดทำ SOP มาตรฐานการบริการที่เป็นมิตรต่อสัตว์เลี้ยง (Pet-Friendly) ควบคู่ไปกับการ ผลักดันแผนก 'หวานตามกาล' เพื่อรังสรรค์เมนูของหวานและไอศกรีมโฮมเมดคราฟต์จากผลไม้ตามฤดูกาล และ พัฒนาแผนกเบเกอรี่ ให้เน้นการผลิตสินค้ากลุ่มของฝากประเภทหิ้วกลับบ้าน (Take-home) ที่มีดีไซน์และบรรจุภัณฑ์ที่พรีเมียม เพื่อสร้างประสบการณ์คาเฟ่ในสวนที่ครบวงจรและพร้อมเติบโตในฐานะเช็คอินสปอตสำคัญของจันทบุรี | S34: สนับสนุนกลุ่มชาวสวนผลไม้เมืองจันท์ผ่านแบรนด์ "หวานตามกาล" และสร้างพื้นที่ส่วนรวม (Community) ที่ปลอดภัยและเป็นมิตรสำหรับครอบครัวและคนรักสัตว์เลี้ยง | T34: ใช้ผลิตภัณฑ์ทำความสะอาดและดูแลสวนที่เป็นออร์แกนิก $100\%$ เพื่อความปลอดภัยของสัตว์เลี้ยง' | U34: ปักหมุดจุดขายคาเฟ่ในสวนด้วยระบบ SOP บริการ Pet-Friendly เต็มรูปแบบ ควบคู่การปั้นของหวาน 'หวานตามกาล' และเบเกอรี่ของฝากพรีเมียมจากผลไม้เมืองจันท์เพื่อขึ้นแท่นเช็คอินสปอตสำคัญในปีนี้ บนฐานความสุขที่ได้เห็นรอยยิ้มของทุกครอบครัวและสัตว์เลี้ยงในพื้นที่ปลอดภัยที่ใช้ออร์แกนิก $100\%$ พร้อมเกื้อกูลชาวสวนท้องถิ่นและทำปุ๋ยหมักหมุนเวียนบำรุงสวนอย่างยั่งยืน | V34: T0
A35: RAP69-034 | B35: เทียบจันท์ | V35: T0
A36: RAP69-035 | B36: The Chanthaboon Coffee กาแฟจันทบูร | R36: 1.เพิ่มยอดขายเฉลี่ยให้ได้ 100,000 บาทต่อเดือน โดยเพิ่มรายได้ต่อหัวของลูกค้าผ่านการจำหน่ายเครื่องดื่ม ขนม และอาหารที่เหมาะกับร้านกาแฟ (ตอนนี้ยังไม่มีเมนู ขนม และ อาหารชัดเจน ซึ่งลูกค้าหลายคนถามหา ว่ามีอาหารทานไหม) รวมถึงการพัฒนาเมนูชุด (Set Menu) เพื่อกระตุ้นการซื้อหลายรายการต่อครั้ง 2.พัฒนาเมนูอาหารและขนมอย่างเป็นทางการ เพื่อสร้างทางเลือกให้ลูกค้า เพิ่มมูลค่าต่อบิล และรองรับการเติบโตของยอดขายในอนาคต 3.วางระบบสต็อกและการจัดซื้อให้มีประสิทธิภาพ เพื่อควบคุมต้นทุน ลดการสูญเสียวัตถุดิบ และป้องกันปัญหาสินค้าขาดสต็อก 4.จัดทำคู่มือการทำงาน (SOP) สำหรับงานหน้าร้านและหลังร้าน เพื่อให้การทำงานมีมาตรฐาน ลดความผิดพลาด และสามารถส่งมอบสินค้าและบริการได้อย่างสม่ำเสมอ 5.พัฒนาระบบบริหารจัดการร้านและกระจายหน้าที่ความรับผิดชอบให้ทีมงาน เพื่อให้ธุรกิจสามารถดำเนินงานได้อย่างเป็นระบบ และลดการพึ่งพาเจ้าของกิจการ 6.ดำเนินการตลาดอย่างต่อเนื่องทั้งออนไลน์และออฟไลน์ เพื่อสร้างการรับรู้แบรนด์ เพิ่มฐานลูกค้าใหม่ รักษาฐานลูกค้าเดิม และสนับสนุนการเติบโตของยอดขาย เป้าหมายสูงสุด ยกระดับกาแฟจันทบูรให้เป็นร้านกาแฟที่มีระบบบริหารจัดการที่เข้มแข็ง มียอดขายเติบโตอย่างยั่งยืน เป็นแหล่งเรียนรู้ด้านกาแฟ และเป็นหนึ่งในจุดหมายปลายทางของนักท่องเที่ยวและคนรักกาแฟในจังหวัดจันทบุรี ::: | S36: -เป็นพื้นที่พบปะ พูดคุย และแลกเปลี่ยนเรียนรู้ของผู้คนทั้งชาวไทยและชาวต่างชาติ -สร้างโอกาสในการเรียนรู้เรื่องกาแฟ ตั้งแต่การปลูก การแปรรูป ไปจนถึงการชงกาแฟ -ถ่ายทอดเรื่องราวประวัติศาสตร์ วัฒนธรรม และวิถีชีวิตของชุมชนจันทบุรีผ่านกาแฟ -สนับสนุนเกษตรกร ผู้ผลิต และผู้ประกอบการในท้องถิ่นให้มีรายได้เพิ่มขึ้นจากกาแฟ -สร้างงานและพัฒนาทักษะให้กับทีมงานและคนในชุมชน -ผลักดันให้ผู้คนทั้งในและต่างประเทศรับรู้ว่าจันทบุรีมีประวัติการปลูกกาแฟมายาวนาน และเป็นแหล่งผลิตกาแฟคุณภาพของไทย | T36: -ส่งเสริมการปลูกกาแฟแบบพืชผสมผสานในสวนดั้งเดิมของเกษตรกร -ช่วยให้เกษตรกรไม่จำเป็นต้องโค่นพืชเศรษฐกิจเดิมทิ้ง แต่สามารถปลูกกาแฟเป็นรายได้เสริมควบคู่กันได้ -สนับสนุนระบบเกษตรที่มีความหลากหลายทางชีวภาพ มากกว่าการปลูกพืชเชิงเดี่ยว -ช่วยรักษาความอุดมสมบูรณ์ของดินและระบบนิเวศภายในสวน -เพิ่มพื้นที่สีเขียวและร่มเงาให้กับแปลงเกษตร -ลดการสูญเสียและของเสียจากการบริหารจัดการวัตถุดิบอย่างมีประสิทธิภาพ -ส่งเสริมการใช้วัตถุดิบจากท้องถิ่น เพื่อลดการขนส่งและสร้างความยั่งยืนให้กับชุมชน | U36: ผลักดันยอดขายสู่ 100,000 บาทต่อเดือนด้วยเมนูและเซ็ตอาหารใหม่ วางระบบสต็อก และ SOP ให้ร้านรันได้เองในปี 2026 บนฐานความสุขที่ได้เล่าขานประวัติศาสตร์และส่งต่อคุณค่ากาแฟจันทบุรีสู่ระดับโลก ควบคู่การสร้างรายได้และพัฒนาทักษะคนในชุมชน พร้อมขับเคลื่อนสิ่งแวดล้อมที่ยั่งยืนผ่านการส่งเสริมเกษตรกรปลูกกาแฟร่วมในสวนดั้งเดิมเพื่อรักษาความหลากหลายทางชีวภาพและระบบนิเวศอย่างมั่นคง | V36: T0
A37: RAP69-036 | B37: Garagecafechan | V37: T0
A38: RAP69-037 | B38: จันทรโภชนา | R38: สร้างและวางตลาดผลิตภัณฑ์ “จันทร” อย่างมีแนวทางที่มั่นคงในระยะยาว ไม่หวือหวา โดยยึดคุณค่าท้องถิ่นสู่มูลค่าทางธุรกิจ | S38: สร้างและวางตลาดผลิตภัณฑ์ “จันทร” กลุ่มเส้นจันท์ และ สมุนไพร นำคุณค่าท้องถิ่นสู่มูลค่าทางธุรกิจ สู่การเป็นเมืองสร้างสรรค์ด้านอาหาร | U38: ยกระดับร้านอาหารจันทรโภชนาควบคู่การวางตลาดผลิตภัณฑ์ 'จันทร' กลุ่มเส้นจันท์และสมุนไพร เพื่อเปลี่ยนคุณค่าท้องถิ่นสู่มูลค่าธุรกิจอย่างมั่นคง บนฐานความสุขที่ได้ขับเคลื่อนจันทบุรีสู่เมืองสร้างสรรค์ด้านอาหาร ตลอดจนยกระดับเศรษฐกิจชุมชนและภูมิปัญญาท้องถิ่นอย่างยั่งยืน | V38: T0
A39: RAP69-038 | B39: Grizzly Gelato | R39: ป้าหมายในปีนี้ 1. ครึ่งปีหลังยอด x2 ของครึ่งปีแรก 2. สร้างช่องติ๊กตอกร้านอาหาร ให้เป็นช่องดัง ผู้ติดตามหลักพันคน 3. ปั้นเพจเฟสบุคร้านไอติมให้ตัวตนชัด 4. สร้างระบบหลังบ้านให้แน่น พร้อมขยายสาขาปีหน้า | S39: เน้นยกระดับวัตถุดิบท้องถิ่น เช่นพวกผลไม้พันธุ์ที่ไม่เป็นที่นิยม หรือขายไม่ได้ราคา เอามาทำเป็นไอติมที่เพิ่มความคิดสร้างสรรค์เข้าไป | U39: ลุยปั๊มยอดขายครึ่งปีหลังให้โตเป็น 2 เท่า ควบคู่การสร้างตัวตนบน TikTok และ Facebook พร้อมเซ็ตระบบหลังบ้านให้แน่นเพื่อเตรียมขยายสาขา บนฐานการทำงานที่มีความสุขผ่านการทำ R&D ไอติมรสชาติใหม่ ๆ ที่ชวนว้าว และมุ่งยกระดับผลไม้ท้องถิ่นสายพันธุ์นอกกระแสให้มีมูลค่าเพิ่ม เพื่อกระจายรายได้และสร้างรอยยิ้มกลับคืนสู่เกษตรกรในชุมชน | V39: T0
A40: RAP69-039 | B40: ครัวตามธาตุ | V40: T0
...

Sheet 02_ประเมิน50ร้าน
A1: รหัสร้าน | B1: ชื่อร้าน | C1: รอบ | D1: วันที่ประเมิน | E1: Q1 | F1: Q2 | G1: Q3 | H1: Q4 | I1: Q5 | J1: Q6 | K1: Q7 | L1: Q8 | M1: Q9 | N1: Q10 | O1: Q11 | P1: Q12 | Q1: Q13 | R1: Q14 | S1: Q15 | T1: Q16 | U1: Q17 | V1: Q18 | W1: Q19 | X1: Q20 | Y1: Q21 | Z1: Q22 | AA1: Q23 | AB1: Q24 | AC1: Q25 | AD1: Q26 | AE1: Q27 | AF1: Q28 | AG1: Q29 | AH1: Q30 | AI1: Q31 | AJ1: Q32 | AK1: Q33 | AL1: Q34 | AM1: Q35 | AN1: Q36 | AO1: Q37 | AP1: Q38 | AQ1: Q39 | AR1: Q40 | AS1: Q41 | AT1: Q42 | AU1: Q43 | AV1: Q44 | AW1: Q45 | AX1: Q46 | AY1: Q47 | AZ1: Q48 | BA1: Q49 | BB1: Q50 | BC1: ความครบถ้วน | BD1: คะแนนดิบ | BE1: คะแนนรวม % | BF1: คะแนนถ่วงน้ำหนัก | BG1: Red Flag | BH1: ระดับรวม | BI1: มิติเร่งแก้ไข | BJ1: มิติ 1 | BK1: มิติ 2 | BL1: มิติ 3 | BM1: มิติ 4 | BN1: มิติ 5 | BO1: มิติ 6 | BP1: มิติ 7 | BQ1: มิติ 8 | BR1: หมายเหตุ/ข้อเสนอแนะ
A2: RAP69-001 | B2: ='01_ข้อมูลร้าน'!B2 -> Seed restaurant | C2: T0 | E2: 2 | F2: 0 | G2: 3 | H2: 0 | I2: 1 | J2: 2 | K2: 4 | L2: 1 | M2: 2 | N2: 0 | O2: 3 | P2: 4 | Q2: 0 | R2: 2 | S2: 4 | T2: 4 | U2: 3 | V2: 4 | W2: 4 | X2: 1 | Y2: 4 | Z2: 4 | AA2: 4 | AB2: 0 | AC2: 4 | AD2: 4 | AE2: 1 | AF2: 2 | AG2: 1 | AH2: 3 | AI2: 1 | AJ2: 2 | AK2: 2 | AL2: 2 | AM2: 0 | AN2: 4 | AO2: 2 | AP2: 0 | AQ2: 1 | AR2: 3 | AS2: 0 | AT2: 2 | AU2: 1 | AV2: 3 | AW2: 4 | AX2: 1 | AY2: 4 | AZ2: 4 | BA2: 3 | BB2: 3 | BC2: =COUNT(E34:BB34)/50 -> 1 | BD2: =SUM(E34:BB34) -> 150 | BE2: =BD2/200 -> 0.75 | BF2: =SUM(E34:K34)/(7*4)*0.12+SUM(L34:R34)/(7*4)*0.15+SUM(S34:X34)/(6*4)*0.1+SUM(Y34:AE34)/(7*4)*0.13+SUM(AF34:AL34)/(7*4)*0.2+SUM(AM34:AS34)/(7*4)*0.18+SUM(AT34:AX34)/(5*4)*0.05+SUM(AY34:BB34)/(4*4)*0.07 -> 0.74145833 | BG2: =COUNTIFS(E34:BB34,">=0",E34:BB34,"<=1") -> 0 | BH2: =IF(BC2=0,"ยังไม่ประเมิน",IF(BF2>=0.8,"ดีมาก",IF(BF2>=0.65,"ดี",IF(BF2>=0.5,"ต้องพัฒนา","เร่งแก้ไข")))) -> ดี | BI2: =IF(BC2=0,"ยังไม่ประเมิน",INDEX($BJ$1:$BQ$1,1,MATCH(MIN(BJ2:BQ2),BJ2:BQ2,0))) -> มิติ 6 | BJ2: =SUM(E34:K34)/(7*4) -> 0.67857143 | BK2: =SUM(L34:R34)/(7*4) -> 0.85714286 | BL2: =SUM(S34:X34)/(6*4) -> 0.83333333 | BM2: =SUM(Y34:AE34)/(7*4) -> 0.71428571 | BN2: =SUM(AF34:AL34)/(7*4) -> 0.71428571 | BO2: =SUM(AM34:AS34)/(7*4) -> 0.60714286 | BP2: =SUM(AT34:AX34)/(5*4) -> 0.75 | BQ2: =SUM(AY34:BB34)/(4*4) -> 0.9375
A3: RAP69-002 | B3: =IFERROR(VLOOKUP(A3,'01_ข้อมูลร้าน'!$A$2:$B$51,2,FALSE),"") -> ก๋วยเตี๋ยวเรือคุณปุ๊ก | C3: T0 | E3: 4 | F3: 0 | G3: 4 | H3: 3 | I3: 4 | J3: 4 | K3: 4 | L3: 3 | M3: 0 | N3: 0 | O3: 0 | P3: 0 | Q3: 0 | R3: 4 | S3: 4 | T3: 3 | U3: 3 | V3: 1 | W3: 2 | X3: 2 | Y3: 1 | Z3: 3 | AA3: 3 | AB3: 1 | AC3: 2 | AD3: 4 | AE3: 1 | AF3: 2 | AG3: 3 | AH3: 3 | AI3: 2 | AJ3: 2 | AK3: 2 | AL3: 2 | AM3: 2 | AN3: 1 | AO3: 3 | AP3: 1 | AQ3: 0 | AR3: 4 | AS3: 4 | AT3: 3 | AU3: 1 | AV3: 3 | AW3: 1 | AX3: 0 | AY3: 3 | AZ3: 3 | BA3: 3 | BB3: 4 | BC3: =COUNT(E3:BB3)/50 -> 1 | BD3: =SUM(E3:BB3) -> 112 | BE3: =BD3/200 -> 0.56 | BF3: =SUM(E3:K3)/(7*4)*0.12+SUM(L3:R3)/(7*4)*0.15+SUM(S3:X3)/(6*4)*0.1+SUM(Y3:AE3)/(7*4)*0.13+SUM(AF3:AL3)/(7*4)*0.2+SUM(AM3:AS3)/(7*4)*0.18+SUM(AT3:AX3)/(5*4)*0.05+SUM(AY3:BB3)/(4*4)*0.07 -> 0.55580357 | BG3: =COUNTIFS(E3:BB3,">=0",E3:BB3,"<=1") -> 16 | BH3: =IF(BC3=0,"ยังไม่ประเมิน",IF(BF3>=0.8,"ดีมาก",IF(BF3>=0.65,"ดี",IF(BF3>=0.5,"ต้องพัฒนา","เร่งแก้ไข")))) -> ต้องพัฒนา | BI3: =IF(BC3=0,"ยังไม่ประเมิน",INDEX($BJ$1:$BQ$1,1,MATCH(MIN(BJ3:BQ3),BJ3:BQ3,0))) -> มิติ 2 | BJ3: =SUM(E3:K3)/(7*4) -> 0.82142857 | BK3: =SUM(L3:R3)/(7*4) -> 0.25 | BL3: =SUM(S3:X3)/(6*4) -> 0.625 | BM3: =SUM(Y3:AE3)/(7*4) -> 0.53571429 | BN3: =SUM(AF3:AL3)/(7*4) -> 0.57142857 | BO3: =SUM(AM3:AS3)/(7*4) -> 0.53571429 | BP3: =SUM(AT3:AX3)/(5*4) -> 0.4 | BQ3: =SUM(AY3:BB3)/(4*4) -> 0.8125
A4: RAP69-003 | B4: =IFERROR(VLOOKUP(A4,'01_ข้อมูลร้าน'!$A$2:$B$51,2,FALSE),"") -> บ้าน-บ้าน สุขพอดี | C4: T0 | E4: 0 | F4: 0 | G4: 0 | H4: 0 | I4: 0 | J4: 3 | K4: 4 | L4: 0 | M4: 0 | N4: 0 | O4: 0 | P4: 0 | Q4: 0 | R4: 0 | S4: 1 | T4: 1 | U4: 2 | V4: 3 | W4: 3 | X4: 2 | Y4: 4 | Z4: 4 | AA4: 4 | AB4: 4 | AC4: 3 | AD4: 3 | AE4: 3 | AF4: 1 | AG4: 2 | AH4: 3 | AI4: 0 | AJ4: 0 | AK4: 1 | AL4: 2 | AM4: 0 | AN4: 0 | AO4: 0 | AP4: 2 | AQ4: 0 | AR4: 1 | AS4: 0 | AT4: 2 | AU4: 4 | AV4: 3 | AW4: 4 | AX4: 4 | AY4: 4 | AZ4: 4 | BA4: 3 | BB4: 4 | BC4: =COUNT(E4:BB4)/50 -> 1 | BD4: =SUM(E4:BB4) -> 88 | BE4: =BD4/200 -> 0.44 | BF4: =SUM(E4:K4)/(7*4)*0.12+SUM(L4:R4)/(7*4)*0.15+SUM(S4:X4)/(6*4)*0.1+SUM(Y4:AE4)/(7*4)*0.13+SUM(AF4:AL4)/(7*4)*0.2+SUM(AM4:AS4)/(7*4)*0.18+SUM(AT4:AX4)/(5*4)*0.05+SUM(AY4:BB4)/(4*4)*0.07 -> 0.38776786 | BG4: =COUNTIFS(E4:BB4,">=0",E4:BB4,"<=1") -> 24 | BH4: =IF(BC4=0,"ยังไม่ประเมิน",IF(BF4>=0.8,"ดีมาก",IF(BF4>=0.65,"ดี",IF(BF4>=0.5,"ต้องพัฒนา","เร่งแก้ไข")))) -> เร่งแก้ไข | BI4: =IF(BC4=0,"ยังไม่ประเมิน",INDEX($BJ$1:$BQ$1,1,MATCH(MIN(BJ4:BQ4),BJ4:BQ4,0))) -> มิติ 2 | BJ4: =SUM(E4:K4)/(7*4) -> 0.25 | BK4: =SUM(L4:R4)/(7*4) -> 0 | BL4: =SUM(S4:X4)/(6*4) -> 0.5 | BM4: =SUM(Y4:AE4)/(7*4) -> 0.89285714 | BN4: =SUM(AF4:AL4)/(7*4) -> 0.32142857 | BO4: =SUM(AM4:AS4)/(7*4) -> 0.10714286 | BP4: =SUM(AT4:AX4)/(5*4) -> 0.85 | BQ4: =SUM(AY4:BB4)/(4*4) -> 0.9375
A5: RAP69-004 | B5: =IFERROR(VLOOKUP(A5,'01_ข้อมูลร้าน'!$A$2:$B$51,2,FALSE),"") -> แฟรนไชส์ก๋วยเตี๋ยวปากหม้อแม่ว่าดี | C5: T0 | E5: 3 | F5: 4 | G5: 4 | H5: 4 | I5: 4 | J5: 3 | K5: 4 | L5: 2 | M5: 2 | N5: 4 | O5: 3 | P5: 2 | Q5: 2 | R5: 1 | S5: 3 | T5: 2 | U5: 4 | V5: 4 | W5: 3 | X5: 3 | Y5: 4 | Z5: 4 | AA5: 4 | AB5: 3 | AC5: 4 | AD5: 3 | AE5: 3 | AF5: 3 | AG5: 4 | AH5: 4 | AI5: 4 | AJ5: 3 | AK5: 3 | AL5: 3 | AM5: 1 | AN5: 2 | AO5: 4 | AP5: 1 | AQ5: 4 | AR5: 4 | AS5: 2 | AT5: 4 | AU5: 3 | AV5: 4 | AW5: 4 | AX5: 4 | AY5: 4 | AZ5: 4 | BA5: 4 | BB5: 3 | BC5: =COUNT(E5:BB5)/50 -> 1 | BD5: =SUM(E5:BB5) -> 162 | BE5: =BD5/200 -> 0.81 | BF5: =SUM(E5:K5)/(7*4)*0.12+SUM(L5:R5)/(7*4)*0.15+SUM(S5:X5)/(6*4)*0.1+SUM(Y5:AE5)/(7*4)*0.13+SUM(AF5:AL5)/(7*4)*0.2+SUM(AM5:AS5)/(7*4)*0.18+SUM(AT5:AX5)/(5*4)*0.05+SUM(AY5:BB5)/(4*4)*0.07 -> 0.79264881 | BG5: =COUNTIFS(E5:BB5,">=0",E5:BB5,"<=1") -> 3 | BH5: =IF(BC5=0,"ยังไม่ประเมิน",IF(BF5>=0.8,"ดีมาก",IF(BF5>=0.65,"ดี",IF(BF5>=0.5,"ต้องพัฒนา","เร่งแก้ไข")))) -> ดี | BI5: =IF(BC5=0,"ยังไม่ประเมิน",INDEX($BJ$1:$BQ$1,1,MATCH(MIN(BJ5:BQ5),BJ5:BQ5,0))) -> มิติ 2 | BJ5: =SUM(E5:K5)/(7*4) -> 0.92857143 | BK5: =SUM(L5:R5)/(7*4) -> 0.57142857 | BL5: =SUM(S5:X5)/(6*4) -> 0.79166667 | BM5: =SUM(Y5:AE5)/(7*4) -> 0.89285714 | BN5: =SUM(AF5:AL5)/(7*4) -> 0.85714286 | BO5: =SUM(AM5:AS5)/(7*4) -> 0.64285714 | BP5: =SUM(AT5:AX5)/(5*4) -> 0.95 | BQ5: =SUM(AY5:BB5)/(4*4) -> 0.9375
A6: RAP69-005 | B6: =IFERROR(VLOOKUP(A6,'01_ข้อมูลร้าน'!$A$2:$B$51,2,FALSE),"") -> 16Brix Melon Farm&Café | C6: T0 | E6: 4 | F6: 3 | G6: 2 | H6: 4 | I6: 4 | J6: 4 | K6: 4 | L6: 1 | M6: 1 | N6: 0 | O6: 2 | P6: 2 | Q6: 4 | R6: 2 | S6: 4 | T6: 4 | U6: 4 | V6: 1 | W6: 4 | X6: 4 | Y6: 4 | Z6: 4 | AA6: 4 | AB6: 0 | AC6: 4 | AD6: 4 | AE6: 3 | AF6: 4 | AG6: 4 | AH6: 3 | AI6: 3 | AJ6: 3 | AK6: 4 | AL6: 4 | AM6: 2 | AN6: 0 | AO6: 2 | AP6: 2 | AQ6: 2 | AR6: 3 | AS6: 3 | AT6: 3 | AU6: 4 | AV6: 4 | AW6: 4 | AX6: 4 | AY6: 3 | AZ6: 4 | BA6: 4 | BB6: 4 | BC6: =COUNT(E6:BB6)/50 -> 1 | BD6: =SUM(E6:BB6) -> 154 | BE6: =BD6/200 -> 0.77 | BF6: =SUM(E6:K6)/(7*4)*0.12+SUM(L6:R6)/(7*4)*0.15+SUM(S6:X6)/(6*4)*0.1+SUM(Y6:AE6)/(7*4)*0.13+SUM(AF6:AL6)/(7*4)*0.2+SUM(AM6:AS6)/(7*4)*0.18+SUM(AT6:AX6)/(5*4)*0.05+SUM(AY6:BB6)/(4*4)*0.07 -> 0.74741071 | BG6: =COUNTIFS(E6:BB6,">=0",E6:BB6,"<=1") -> 6 | BH6: =IF(BC6=0,"ยังไม่ประเมิน",IF(BF6>=0.8,"ดีมาก",IF(BF6>=0.65,"ดี",IF(BF6>=0.5,"ต้องพัฒนา","เร่งแก้ไข")))) -> ดี | BI6: =IF(BC6=0,"ยังไม่ประเมิน",INDEX($BJ$1:$BQ$1,1,MATCH(MIN(BJ6:BQ6),BJ6:BQ6,0))) -> มิติ 2 | BJ6: =SUM(E6:K6)/(7*4) -> 0.89285714 | BK6: =SUM(L6:R6)/(7*4) -> 0.42857143 | BL6: =SUM(S6:X6)/(6*4) -> 0.875 | BM6: =SUM(Y6:AE6)/(7*4) -> 0.82142857 | BN6: =SUM(AF6:AL6)/(7*4) -> 0.89285714 | BO6: =SUM(AM6:AS6)/(7*4) -> 0.5 | BP6: =SUM(AT6:AX6)/(5*4) -> 0.95 | BQ6: =SUM(AY6:BB6)/(4*4) -> 0.9375
A7: RAP69-006 | B7: =IFERROR(VLOOKUP(A7,'01_ข้อมูลร้าน'!$A$2:$B$51,2,FALSE),"") -> ร้านอีสานเฮาส์ (304 ปราจีนบุรี) | C7: T0 | E7: 4 | F7: 0 | G7: 1 | H7: 4 | I7: 4 | J7: 3 | K7: 4 | L7: 4 | M7: 4 | N7: 3 | O7: 3 | P7: 4 | Q7: 4 | R7: 4 | S7: 4 | T7: 4 | U7: 4 | V7: 4 | W7: 4 | X7: 4 | Y7: 4 | Z7: 4 | AA7: 4 | AB7: 4 | AC7: 4 | AD7: 4 | AE7: 4 | AF7: 3 | AG7: 3 | AH7: 3 | AI7: 3 | AJ7: 3 | AK7: 3 | AL7: 4 | AM7: 4 | AN7: 4 | AO7: 2 | AP7: 4 | AQ7: 2 | AR7: 2 | AS7: 4 | AT7: 4 | AU7: 3 | AV7: 4 | AW7: 4 | AX7: 4 | AY7: 4 | AZ7: 4 | BA7: 4 | BB7: 4 | BC7: =COUNT(E7:BB7)/50 -> 1 | BD7: =SUM(E7:BB7) -> 177 | BE7: =BD7/200 -> 0.885 | BF7: =SUM(E7:K7)/(7*4)*0.12+SUM(L7:R7)/(7*4)*0.15+SUM(S7:X7)/(6*4)*0.1+SUM(Y7:AE7)/(7*4)*0.13+SUM(AF7:AL7)/(7*4)*0.2+SUM(AM7:AS7)/(7*4)*0.18+SUM(AT7:AX7)/(5*4)*0.05+SUM(AY7:BB7)/(4*4)*0.07 -> 0.87107143 | BG7: =COUNTIFS(E7:BB7,">=0",E7:BB7,"<=1") -> 2 | BH7: =IF(BC7=0,"ยังไม่ประเมิน",IF(BF7>=0.8,"ดีมาก",IF(BF7>=0.65,"ดี",IF(BF7>=0.5,"ต้องพัฒนา","เร่งแก้ไข")))) -> ดีมาก | BI7: =IF(BC7=0,"ยังไม่ประเมิน",INDEX($BJ$1:$BQ$1,1,MATCH(MIN(BJ7:BQ7),BJ7:BQ7,0))) -> มิติ 1 | BJ7: =SUM(E7:K7)/(7*4) -> 0.71428571 | BK7: =SUM(L7:R7)/(7*4) -> 0.92857143 | BL7: =SUM(S7:X7)/(6*4) -> 1 | BM7: =SUM(Y7:AE7)/(7*4) -> 1 | BN7: =SUM(AF7:AL7)/(7*4) -> 0.78571429 | BO7: =SUM(AM7:AS7)/(7*4) -> 0.78571429 | BP7: =SUM(AT7:AX7)/(5*4) -> 0.95 | BQ7: =SUM(AY7:BB7)/(4*4) -> 1
A8: RAP69-007 | B8: =IFERROR(VLOOKUP(A8,'01_ข้อมูลร้าน'!$A$2:$B$51,2,FALSE),"") -> ร้านคำนิยม | C8: T0 | E8: 4 | F8: 3 | G8: 1 | H8: 4 | I8: 3 | J8: 3 | K8: 3 | L8: 3 | M8: 4 | N8: 2 | O8: 1 | P8: 4 | Q8: 4 | R8: 4 | S8: 4 | T8: 4 | U8: 4 | V8: 3 | W8: 4 | X8: 3 | Y8: 4 | Z8: 4 | AA8: 4 | AB8: 4 | AC8: 4 | AD8: 4 | AE8: 2 | AF8: 3 | AG8: 2 | AH8: 1 | AI8: 3 | AJ8: 3 | AK8: 3 | AL8: 2 | AM8: 2 | AN8: 2 | AO8: 3 | AP8: 4 | AQ8: 2 | AR8: 3 | AS8: 4 | AT8: 4 | AU8: 2 | AV8: 4 | AW8: 3 | AX8: 4 | AY8: 4 | AZ8: 4 | BA8: 4 | BB8: 4 | BC8: =COUNT(E8:BB8)/50 -> 1 | BD8: =SUM(E8:BB8) -> 161 | BE8: =BD8/200 -> 0.805 | BF8: =SUM(E8:K8)/(7*4)*0.12+SUM(L8:R8)/(7*4)*0.15+SUM(S8:X8)/(6*4)*0.1+SUM(Y8:AE8)/(7*4)*0.13+SUM(AF8:AL8)/(7*4)*0.2+SUM(AM8:AS8)/(7*4)*0.18+SUM(AT8:AX8)/(5*4)*0.05+SUM(AY8:BB8)/(4*4)*0.07 -> 0.7827381 | BG8: =COUNTIFS(E8:BB8,">=0",E8:BB8,"<=1") -> 3 | BH8: =IF(BC8=0,"ยังไม่ประเมิน",IF(BF8>=0.8,"ดีมาก",IF(BF8>=0.65,"ดี",IF(BF8>=0.5,"ต้องพัฒนา","เร่งแก้ไข")))) -> ดี | BI8: =IF(BC8=0,"ยังไม่ประเมิน",INDEX($BJ$1:$BQ$1,1,MATCH(MIN(BJ8:BQ8),BJ8:BQ8,0))) -> มิติ 5 | BJ8: =SUM(E8:K8)/(7*4) -> 0.75 | BK8: =SUM(L8:R8)/(7*4) -> 0.78571429 | BL8: =SUM(S8:X8)/(6*4) -> 0.91666667 | BM8: =SUM(Y8:AE8)/(7*4) -> 0.92857143 | BN8: =SUM(AF8:AL8)/(7*4) -> 0.60714286 | BO8: =SUM(AM8:AS8)/(7*4) -> 0.71428571 | BP8: =SUM(AT8:AX8)/(5*4) -> 0.85 | BQ8: =SUM(AY8:BB8)/(4*4) -> 1
A9: RAP69-008 | B9: =IFERROR(VLOOKUP(A9,'01_ข้อมูลร้าน'!$A$2:$B$51,2,FALSE),"") -> ร้านอรวรรณบ้านเพ | C9: T0 | E9: 4 | F9: 0 | G9: 0 | H9: 1 | I9: 2 | J9: 2 | K9: 3 | L9: 0 | M9: 0 | N9: 0 | O9: 0 | P9: 0 | Q9: 4 | R9: 0 | S9: 1 | T9: 2 | U9: 4 | V9: 1 | W9: 1 | X9: 1 | Y9: 0 | Z9: 4 | AA9: 4 | AB9: 1 | AC9: 1 | AD9: 1 | AE9: 1 | AF9: 1 | AG9: 2 | AH9: 0 | AI9: 1 | AJ9: 2 | AK9: 2 | AL9: 1 | AM9: 1 | AN9: 1 | AO9: 3 | AP9: 0 | AQ9: 0 | AR9: 3 | AS9: 3 | AT9: 3 | AU9: 4 | AV9: 3 | AW9: 2 | AX9: 3 | AY9: 4 | AZ9: 4 | BA9: 3 | BB9: 3 | BC9: =COUNT(E9:BB9)/50 -> 1 | BD9: =SUM(E9:BB9) -> 87 | BE9: =BD9/200 -> 0.435 | BF9: =SUM(E9:K9)/(7*4)*0.12+SUM(L9:R9)/(7*4)*0.15+SUM(S9:X9)/(6*4)*0.1+SUM(Y9:AE9)/(7*4)*0.13+SUM(AF9:AL9)/(7*4)*0.2+SUM(AM9:AS9)/(7*4)*0.18+SUM(AT9:AX9)/(5*4)*0.05+SUM(AY9:BB9)/(4*4)*0.07 -> 0.4039881 | BG9: =COUNTIFS(E9:BB9,">=0",E9:BB9,"<=1") -> 26 | BH9: =IF(BC9=0,"ยังไม่ประเมิน",IF(BF9>=0.8,"ดีมาก",IF(BF9>=0.65,"ดี",IF(BF9>=0.5,"ต้องพัฒนา","เร่งแก้ไข")))) -> เร่งแก้ไข | BI9: =IF(BC9=0,"ยังไม่ประเมิน",INDEX($BJ$1:$BQ$1,1,MATCH(MIN(BJ9:BQ9),BJ9:BQ9,0))) -> มิติ 2 | BJ9: =SUM(E9:K9)/(7*4) -> 0.42857143 | BK9: =SUM(L9:R9)/(7*4) -> 0.14285714 | BL9: =SUM(S9:X9)/(6*4) -> 0.41666667 | BM9: =SUM(Y9:AE9)/(7*4) -> 0.42857143 | BN9: =SUM(AF9:AL9)/(7*4) -> 0.32142857 | BO9: =SUM(AM9:AS9)/(7*4) -> 0.39285714 | BP9: =SUM(AT9:AX9)/(5*4) -> 0.75 | BQ9: =SUM(AY9:BB9)/(4*4) -> 0.875
A10: RAP69-009 | B10: =IFERROR(VLOOKUP(A10,'01_ข้อมูลร้าน'!$A$2:$B$51,2,FALSE),"") -> ครัวเดอมอง | C10: T0 | E10: 4 | F10: 3 | G10: 4 | H10: 2 | I10: 3 | J10: 2 | K10: 3 | L10: 0 | M10: 2 | N10: 0 | O10: 2 | P10: 0 | Q10: 4 | R10: 3 | S10: 4 | T10: 1 | U10: 2 | V10: 0 | W10: 1 | X10: 0 | Y10: 3 | Z10: 0 | AA10: 3 | AB10: 0 | AC10: 0 | AD10: 1 | AE10: 0 | AF10: 1 | AG10: 1 | AH10: 0 | AI10: 1 | AJ10: 2 | AK10: 2 | AL10: 1 | AM10: 1 | AN10: 0 | AO10: 3 | AP10: 0 | AQ10: 1 | AR10: 4 | AS10: 2 | AT10: 2 | AU10: 3 | AV10: 2 | AW10: 3 | AX10: 0 | AY10: 3 | AZ10: 4 | BA10: 3 | BB10: 3 | BC10: =COUNT(E10:BB10)/50 -> 1 | BD10: =SUM(E10:BB10) -> 89 | BE10: =BD10/200 -> 0.445 | BF10: =SUM(E10:K10)/(7*4)*0.12+SUM(L10:R10)/(7*4)*0.15+SUM(S10:X10)/(6*4)*0.1+SUM(Y10:AE10)/(7*4)*0.13+SUM(AF10:AL10)/(7*4)*0.2+SUM(AM10:AS10)/(7*4)*0.18+SUM(AT10:AX10)/(5*4)*0.05+SUM(AY10:BB10)/(4*4)*0.07 -> 0.42449405 | BG10: =COUNTIFS(E10:BB10,">=0",E10:BB10,"<=1") -> 22 | BH10: =IF(BC10=0,"ยังไม่ประเมิน",IF(BF10>=0.8,"ดีมาก",IF(BF10>=0.65,"ดี",IF(BF10>=0.5,"ต้องพัฒนา","เร่งแก้ไข")))) -> เร่งแก้ไข | BI10: =IF(BC10=0,"ยังไม่ประเมิน",INDEX($BJ$1:$BQ$1,1,MATCH(MIN(BJ10:BQ10),BJ10:BQ10,0))) -> มิติ 4 | BJ10: =SUM(E10:K10)/(7*4) -> 0.75 | BK10: =SUM(L10:R10)/(7*4) -> 0.39285714 | BL10: =SUM(S10:X10)/(6*4) -> 0.33333333 | BM10: =SUM(Y10:AE10)/(7*4) -> 0.25 | BN10: =SUM(AF10:AL10)/(7*4) -> 0.28571429 | BO10: =SUM(AM10:AS10)/(7*4) -> 0.39285714 | BP10: =SUM(AT10:AX10)/(5*4) -> 0.5 | BQ10: =SUM(AY10:BB10)/(4*4) -> 0.8125
A11: RAP69-010 | B11: =IFERROR(VLOOKUP(A11,'01_ข้อมูลร้าน'!$A$2:$B$51,2,FALSE),"") -> เรือนไทย พัทยา | C11: T0 | E11: 4 | F11: 1 | G11: 0 | H11: 1 | I11: 1 | J11: 3 | K11: 4 | L11: 2 | M11: 0 | N11: 4 | O11: 0 | P11: 2 | Q11: 4 | R11: 4 | AM11: 4 | AN11: 1 | AO11: 4 | AP11: 1 | AQ11: 0 | AR11: 4 | AS11: 4 | AT11: 4 | AU11: 3 | AV11: 4 | AW11: 2 | AX11: 4 | AY11: 4 | AZ11: 4 | BA11: 4 | BB11: 1 | BC11: =COUNT(E11:BB11)/50 -> 0.6 | BD11: =SUM(E11:BB11) -> 78 | BE11: =BD11/200 -> 0.39 | BF11: =SUM(E11:K11)/(7*4)*0.12+SUM(L11:R11)/(7*4)*0.15+SUM(S11:X11)/(6*4)*0.1+SUM(Y11:AE11)/(7*4)*0.13+SUM(AF11:AL11)/(7*4)*0.2+SUM(AM11:AS11)/(7*4)*0.18+SUM(AT11:AX11)/(5*4)*0.05+SUM(AY11:BB11)/(4*4)*0.07 -> 0.36080357 | BG11: =COUNTIFS(E11:BB11,">=0",E11:BB11,"<=1") -> 10 | BH11: =IF(BC11=0,"ยังไม่ประเมิน",IF(BF11>=0.8,"ดีมาก",IF(BF11>=0.65,"ดี",IF(BF11>=0.5,"ต้องพัฒนา","เร่งแก้ไข")))) -> เร่งแก้ไข | BI11: =IF(BC11=0,"ยังไม่ประเมิน",INDEX($BJ$1:$BQ$1,1,MATCH(MIN(BJ11:BQ11),BJ11:BQ11,0))) -> มิติ 3 | BJ11: =SUM(E11:K11)/(7*4) -> 0.5 | BK11: =SUM(L11:R11)/(7*4) -> 0.57142857 | BL11: =SUM(S11:X11)/(6*4) -> 0 | BM11: =SUM(Y11:AE11)/(7*4) -> 0 | BN11: =SUM(AF11:AL11)/(7*4) -> 0 | BO11: =SUM(AM11:AS11)/(7*4) -> 0.64285714 | BP11: =SUM(AT11:AX11)/(5*4) -> 0.85 | BQ11: =SUM(AY11:BB11)/(4*4) -> 0.8125
A12: RAP69-011 | B12: =IFERROR(VLOOKUP(A12,'01_ข้อมูลร้าน'!$A$2:$B$51,2,FALSE),"") -> ร้านอาหาร ทะเลลานโพธิ์ ซีฟู้ด | C12: T0 | E12: 3 | F12: 3 | G12: 3 | H12: 1 | I12: 2 | J12: 3 | K12: 1 | L12: 4 | M12: 4 | N12: 4 | O12: 3 | P12: 0 | Q12: 4 | R12: 3 | S12: 4 | T12: 3 | U12: 3 | V12: 2 | W12: 4 | X12: 1 | Y12: 3 | Z12: 2 | AA12: 3 | AB12: 2 | AC12: 1 | AD12: 2 | AE12: 3 | AF12: 2 | AG12: 3 | AH12: 2 | AI12: 2 | AJ12: 3 | AK12: 2 | AL12: 2 | AM12: 4 | AN12: 2 | AO12: 3 | AP12: 4 | AQ12: 3 | AR12: 4 | AS12: 2 | AT12: 3 | AU12: 2 | AV12: 3 | AW12: 3 | AX12: 2 | AY12: 3 | AZ12: 3 | BA12: 3 | BB12: 3 | BC12: =COUNT(E12:BB12)/50 -> 1 | BD12: =SUM(E12:BB12) -> 134 | BE12: =BD12/200 -> 0.67 | BF12: =SUM(E12:K12)/(7*4)*0.12+SUM(L12:R12)/(7*4)*0.15+SUM(S12:X12)/(6*4)*0.1+SUM(Y12:AE12)/(7*4)*0.13+SUM(AF12:AL12)/(7*4)*0.2+SUM(AM12:AS12)/(7*4)*0.18+SUM(AT12:AX12)/(5*4)*0.05+SUM(AY12:BB12)/(4*4)*0.07 -> 0.6722619 | BG12: =COUNTIFS(E12:BB12,">=0",E12:BB12,"<=1") -> 5 | BH12: =IF(BC12=0,"ยังไม่ประเมิน",IF(BF12>=0.8,"ดีมาก",IF(BF12>=0.65,"ดี",IF(BF12>=0.5,"ต้องพัฒนา","เร่งแก้ไข")))) -> ดี | BI12: =IF(BC12=0,"ยังไม่ประเมิน",INDEX($BJ$1:$BQ$1,1,MATCH(MIN(BJ12:BQ12),BJ12:BQ12,0))) -> มิติ 1 | BJ12: =SUM(E12:K12)/(7*4) -> 0.57142857 | BK12: =SUM(L12:R12)/(7*4) -> 0.78571429 | BL12: =SUM(S12:X12)/(6*4) -> 0.70833333 | BM12: =SUM(Y12:AE12)/(7*4) -> 0.57142857 | BN12: =SUM(AF12:AL12)/(7*4) -> 0.57142857 | BO12: =SUM(AM12:AS12)/(7*4) -> 0.78571429 | BP12: =SUM(AT12:AX12)/(5*4) -> 0.65 | BQ12: =SUM(AY12:BB12)/(4*4) -> 0.75
A13: RAP69-012 | B13: =IFERROR(VLOOKUP(A13,'01_ข้อมูลร้าน'!$A$2:$B$51,2,FALSE),"") -> นายกุ่ยไก่หุบบอน @เขาชีจรรย์ | C13: T0 | E13: 4 | F13: 2 | G13: 3 | H13: 1 | I13: 4 | J13: 1 | K13: 3 | L13: 3 | M13: 3 | N13: 3 | O13: 2 | P13: 3 | Q13: 3 | R13: 3 | S13: 4 | T13: 3 | U13: 4 | V13: 3 | W13: 2 | X13: 1 | Y13: 2 | Z13: 2 | AA13: 2 | AB13: 1 | AC13: 1 | AD13: 2 | AE13: 2 | AF13: 2 | AG13: 2 | AH13: 1 | AI13: 3 | AJ13: 3 | AK13: 3 | AL13: 3 | AM13: 3 | AN13: 3 | AO13: 3 | AP13: 3 | AQ13: 3 | AR13: 3 | AS13: 3 | AT13: 4 | AU13: 4 | AV13: 3 | AW13: 3 | AX13: 4 | AY13: 3 | AZ13: 3 | BA13: 3 | BB13: 2 | BC13: =COUNT(E13:BB13)/50 -> 1 | BD13: =SUM(E13:BB13) -> 134 | BE13: =BD13/200 -> 0.67 | BF13: =SUM(E13:K13)/(7*4)*0.12+SUM(L13:R13)/(7*4)*0.15+SUM(S13:X13)/(6*4)*0.1+SUM(Y13:AE13)/(7*4)*0.13+SUM(AF13:AL13)/(7*4)*0.2+SUM(AM13:AS13)/(7*4)*0.18+SUM(AT13:AX13)/(5*4)*0.05+SUM(AY13:BB13)/(4*4)*0.07 -> 0.6603869 | BG13: =COUNTIFS(E13:BB13,">=0",E13:BB13,"<=1") -> 6 | BH13: =IF(BC13=0,"ยังไม่ประเมิน",IF(BF13>=0.8,"ดีมาก",IF(BF13>=0.65,"ดี",IF(BF13>=0.5,"ต้องพัฒนา","เร่งแก้ไข")))) -> ดี | BI13: =IF(BC13=0,"ยังไม่ประเมิน",INDEX($BJ$1:$BQ$1,1,MATCH(MIN(BJ13:BQ13),BJ13:BQ13,0))) -> มิติ 4 | BJ13: =SUM(E13:K13)/(7*4) -> 0.64285714 | BK13: =SUM(L13:R13)/(7*4) -> 0.71428571 | BL13: =SUM(S13:X13)/(6*4) -> 0.70833333 | BM13: =SUM(Y13:AE13)/(7*4) -> 0.42857143 | BN13: =SUM(AF13:AL13)/(7*4) -> 0.60714286 | BO13: =SUM(AM13:AS13)/(7*4) -> 0.75 | BP13: =SUM(AT13:AX13)/(5*4) -> 0.9 | BQ13: =SUM(AY13:BB13)/(4*4) -> 0.6875
A14: RAP69-013 | B14: =IFERROR(VLOOKUP(A14,'01_ข้อมูลร้าน'!$A$2:$B$51,2,FALSE),"") -> บ้านสวนบางแสน | C14: T0 | E14: 4 | F14: 2 | G14: 2 | H14: 1 | I14: 2 | J14: 2 | K14: 1 | L14: 3 | M14: 2 | N14: 2 | O14: 1 | P14: 3 | Q14: 0 | R14: 3 | S14: 4 | T14: 3 | U14: 2 | V14: 0 | W14: 2 | X14: 2 | Y14: 3 | Z14: 3 | AA14: 2 | AB14: 1 | AC14: 1 | AD14: 1 | AE14: 1 | AF14: 1 | AG14: 2 | AH14: 3 | AI14: 4 | AJ14: 2 | AK14: 3 | AL14: 1 | AM14: 3 | AN14: 3 | AO14: 4 | AP14: 3 | AQ14: 1 | AR14: 4 | AS14: 3 | AT14: 3 | AU14: 3 | AV14: 1 | AW14: 3 | AX14: 0 | AY14: 3 | AZ14: 3 | BA14: 3 | BB14: 2 | BC14: =COUNT(E14:BB14)/50 -> 1 | BD14: =SUM(E14:BB14) -> 111 | BE14: =BD14/200 -> 0.555 | BF14: =SUM(E14:K14)/(7*4)*0.12+SUM(L14:R14)/(7*4)*0.15+SUM(S14:X14)/(6*4)*0.1+SUM(Y14:AE14)/(7*4)*0.13+SUM(AF14:AL14)/(7*4)*0.2+SUM(AM14:AS14)/(7*4)*0.18+SUM(AT14:AX14)/(5*4)*0.05+SUM(AY14:BB14)/(4*4)*0.07 -> 0.56729167 | BG14: =COUNTIFS(E14:BB14,">=0",E14:BB14,"<=1") -> 14 | BH14: =IF(BC14=0,"ยังไม่ประเมิน",IF(BF14>=0.8,"ดีมาก",IF(BF14>=0.65,"ดี",IF(BF14>=0.5,"ต้องพัฒนา","เร่งแก้ไข")))) -> ต้องพัฒนา | BI14: =IF(BC14=0,"ยังไม่ประเมิน",INDEX($BJ$1:$BQ$1,1,MATCH(MIN(BJ14:BQ14),BJ14:BQ14,0))) -> มิติ 4 | BJ14: =SUM(E14:K14)/(7*4) -> 0.5 | BK14: =SUM(L14:R14)/(7*4) -> 0.5 | BL14: =SUM(S14:X14)/(6*4) -> 0.54166667 | BM14: =SUM(Y14:AE14)/(7*4) -> 0.42857143 | BN14: =SUM(AF14:AL14)/(7*4) -> 0.57142857 | BO14: =SUM(AM14:AS14)/(7*4) -> 0.75 | BP14: =SUM(AT14:AX14)/(5*4) -> 0.5 | BQ14: =SUM(AY14:BB14)/(4*4) -> 0.6875
A15: RAP69-014 | B15: =IFERROR(VLOOKUP(A15,'01_ข้อมูลร้าน'!$A$2:$B$51,2,FALSE),"") -> สวนแววอรุณ | C15: T0 | E15: 4 | F15: 4 | G15: 0 | H15: 4 | I15: 0 | J15: 3 | K15: 3 | L15: 3 | M15: 3 | N15: 2 | O15: 2 | P15: 2 | Q15: 3 | R15: 3 | S15: 4 | T15: 3 | U15: 3 | V15: 3 | W15: 4 | X15: 1 | Y15: 2 | Z15: 2 | AA15: 3 | AB15: 2 | AC15: 3 | AD15: 2 | AE15: 3 | AF15: 3 | AG15: 2 | AH15: 3 | AI15: 3 | AJ15: 3 | AK15: 2 | AL15: 3 | AM15: 3 | AN15: 3 | AO15: 3 | AP15: 2 | AQ15: 3 | AR15: 2 | AS15: 2 | AT15: 4 | AU15: 2 | AV15: 3 | AW15: 2 | AX15: 1 | AY15: 3 | AZ15: 3 | BA15: 3 | BB15: 2 | BC15: =COUNT(E15:BB15)/50 -> 1 | BD15: =SUM(E15:BB15) -> 131 | BE15: =BD15/200 -> 0.655 | BF15: =SUM(E15:K15)/(7*4)*0.12+SUM(L15:R15)/(7*4)*0.15+SUM(S15:X15)/(6*4)*0.1+SUM(Y15:AE15)/(7*4)*0.13+SUM(AF15:AL15)/(7*4)*0.2+SUM(AM15:AS15)/(7*4)*0.18+SUM(AT15:AX15)/(5*4)*0.05+SUM(AY15:BB15)/(4*4)*0.07 -> 0.65705357 | BG15: =COUNTIFS(E15:BB15,">=0",E15:BB15,"<=1") -> 4 | BH15: =IF(BC15=0,"ยังไม่ประเมิน",IF(BF15>=0.8,"ดีมาก",IF(BF15>=0.65,"ดี",IF(BF15>=0.5,"ต้องพัฒนา","เร่งแก้ไข")))) -> ดี | BI15: =IF(BC15=0,"ยังไม่ประเมิน",INDEX($BJ$1:$BQ$1,1,MATCH(MIN(BJ15:BQ15),BJ15:BQ15,0))) -> มิติ 7 | BJ15: =SUM(E15:K15)/(7*4) -> 0.64285714 | BK15: =SUM(L15:R15)/(7*4) -> 0.64285714 | BL15: =SUM(S15:X15)/(6*4) -> 0.75 | BM15: =SUM(Y15:AE15)/(7*4) -> 0.60714286 | BN15: =SUM(AF15:AL15)/(7*4) -> 0.67857143 | BO15: =SUM(AM15:AS15)/(7*4) -> 0.64285714 | BP15: =SUM(AT15:AX15)/(5*4) -> 0.6 | BQ15: =SUM(AY15:BB15)/(4*4) -> 0.6875
A16: RAP69-015 | B16: =IFERROR(VLOOKUP(A16,'01_ข้อมูลร้าน'!$A$2:$B$51,2,FALSE),"") -> คุณอี๊ดกะเพราแซ่บจี้ด | C16: T0 | E16: 2 | F16: 2 | G16: 3 | H16: 1 | I16: 1 | J16: 1 | K16: 2 | L16: 1 | M16: 1 | N16: 2 | O16: 2 | P16: 3 | Q16: 2 | R16: 2 | S16: 1 | T16: 1 | U16: 2 | V16: 2 | W16: 1 | X16: 1 | Y16: 0 | Z16: 0 | AA16: 0 | AB16: 2 | AC16: 1 | AD16: 1 | AE16: 1 | AF16: 2 | AG16: 2 | AH16: 0 | AI16: 0 | AJ16: 2 | AK16: 2 | AL16: 4 | AM16: 1 | AN16: 2 | AO16: 3 | AP16: 2 | AQ16: 1 | AR16: 4 | AS16: 1 | AT16: 2 | AU16: 1 | AV16: 3 | AW16: 1 | AX16: 2 | AY16: 3 | AZ16: 3 | BA16: 3 | BB16: 2 | BC16: =COUNT(E16:BB16)/50 -> 1 | BD16: =SUM(E16:BB16) -> 84 | BE16: =BD16/200 -> 0.42 | BF16: =SUM(E16:K16)/(7*4)*0.12+SUM(L16:R16)/(7*4)*0.15+SUM(S16:X16)/(6*4)*0.1+SUM(Y16:AE16)/(7*4)*0.13+SUM(AF16:AL16)/(7*4)*0.2+SUM(AM16:AS16)/(7*4)*0.18+SUM(AT16:AX16)/(5*4)*0.05+SUM(AY16:BB16)/(4*4)*0.07 -> 0.42395833 | BG16: =COUNTIFS(E16:BB16,">=0",E16:BB16,"<=1") -> 22 | BH16: =IF(BC16=0,"ยังไม่ประเมิน",IF(BF16>=0.8,"ดีมาก",IF(BF16>=0.65,"ดี",IF(BF16>=0.5,"ต้องพัฒนา","เร่งแก้ไข")))) -> เร่งแก้ไข | BI16: =IF(BC16=0,"ยังไม่ประเมิน",INDEX($BJ$1:$BQ$1,1,MATCH(MIN(BJ16:BQ16),BJ16:BQ16,0))) -> มิติ 4 | BJ16: =SUM(E16:K16)/(7*4) -> 0.42857143 | BK16: =SUM(L16:R16)/(7*4) -> 0.46428571 | BL16: =SUM(S16:X16)/(6*4) -> 0.33333333 | BM16: =SUM(Y16:AE16)/(7*4) -> 0.17857143 | BN16: =SUM(AF16:AL16)/(7*4) -> 0.42857143 | BO16: =SUM(AM16:AS16)/(7*4) -> 0.5 | BP16: =SUM(AT16:AX16)/(5*4) -> 0.45 | BQ16: =SUM(AY16:BB16)/(4*4) -> 0.6875
A17: RAP69-016 | B17: =IFERROR(VLOOKUP(A17,'01_ข้อมูลร้าน'!$A$2:$B$51,2,FALSE),"") -> หมูสะเต๊ะอพอลโล | C17: T0 | BC17: =COUNT(E17:BB17)/50 -> 0 | BD17: =SUM(E17:BB17) -> 0 | BE17: =BD17/200 -> 0 | BF17: =SUM(E17:K17)/(7*4)*0.12+SUM(L17:R17)/(7*4)*0.15+SUM(S17:X17)/(6*4)*0.1+SUM(Y17:AE17)/(7*4)*0.13+SUM(AF17:AL17)/(7*4)*0.2+SUM(AM17:AS17)/(7*4)*0.18+SUM(AT17:AX17)/(5*4)*0.05+SUM(AY17:BB17)/(4*4)*0.07 -> 0 | BG17: =COUNTIFS(E17:BB17,">=0",E17:BB17,"<=1") -> 0 | BH17: =IF(BC17=0,"ยังไม่ประเมิน",IF(BF17>=0.8,"ดีมาก",IF(BF17>=0.65,"ดี",IF(BF17>=0.5,"ต้องพัฒนา","เร่งแก้ไข")))) -> ยังไม่ประเมิน | BI17: =IF(BC17=0,"ยังไม่ประเมิน",INDEX($BJ$1:$BQ$1,1,MATCH(MIN(BJ17:BQ17),BJ17:BQ17,0))) -> ยังไม่ประเมิน | BJ17: =SUM(E17:K17)/(7*4) -> 0 | BK17: =SUM(L17:R17)/(7*4) -> 0 | BL17: =SUM(S17:X17)/(6*4) -> 0 | BM17: =SUM(Y17:AE17)/(7*4) -> 0 | BN17: =SUM(AF17:AL17)/(7*4) -> 0 | BO17: =SUM(AM17:AS17)/(7*4) -> 0 | BP17: =SUM(AT17:AX17)/(5*4) -> 0 | BQ17: =SUM(AY17:BB17)/(4*4) -> 0
A18: RAP69-017 | B18: =IFERROR(VLOOKUP(A18,'01_ข้อมูลร้าน'!$A$2:$B$51,2,FALSE),"") -> วันวาน คาเฟ่ | C18: T0 | E18: 2 | F18: 1 | G18: 1 | H18: 2 | I18: 1 | J18: 2 | K18: 1 | L18: 3 | M18: 3 | N18: 2 | O18: 1 | P18: 2 | Q18: 0 | R18: 2 | S18: 3 | T18: 2 | U18: 2 | V18: 0 | W18: 2 | X18: 1 | Y18: 2 | Z18: 2 | AA18: 2 | AB18: 2 | AC18: 0 | AD18: 1 | AE18: 2 | AF18: 1 | AG18: 2 | AH18: 0 | AI18: 3 | AJ18: 3 | AK18: 2 | AL18: 1 | AM18: 2 | AN18: 2 | AO18: 2 | AP18: 2 | AQ18: 3 | AR18: 2 | AS18: 3 | AT18: 2 | AU18: 1 | AV18: 1 | AW18: 0 | AX18: 0 | AY18: 2 | AZ18: 2 | BA18: 2 | BB18: 2 | BC18: =COUNT(E18:BB18)/50 -> 1 | BD18: =SUM(E18:BB18) -> 84 | BE18: =BD18/200 -> 0.42 | BF18: =SUM(E18:K18)/(7*4)*0.12+SUM(L18:R18)/(7*4)*0.15+SUM(S18:X18)/(6*4)*0.1+SUM(Y18:AE18)/(7*4)*0.13+SUM(AF18:AL18)/(7*4)*0.2+SUM(AM18:AS18)/(7*4)*0.18+SUM(AT18:AX18)/(5*4)*0.05+SUM(AY18:BB18)/(4*4)*0.07 -> 0.43880952 | BG18: =COUNTIFS(E18:BB18,">=0",E18:BB18,"<=1") -> 17 | BH18: =IF(BC18=0,"ยังไม่ประเมิน",IF(BF18>=0.8,"ดีมาก",IF(BF18>=0.65,"ดี",IF(BF18>=0.5,"ต้องพัฒนา","เร่งแก้ไข")))) -> เร่งแก้ไข | BI18: =IF(BC18=0,"ยังไม่ประเมิน",INDEX($BJ$1:$BQ$1,1,MATCH(MIN(BJ18:BQ18),BJ18:BQ18,0))) -> มิติ 7 | BJ18: =SUM(E18:K18)/(7*4) -> 0.35714286 | BK18: =SUM(L18:R18)/(7*4) -> 0.46428571 | BL18: =SUM(S18:X18)/(6*4) -> 0.41666667 | BM18: =SUM(Y18:AE18)/(7*4) -> 0.39285714 | BN18: =SUM(AF18:AL18)/(7*4) -> 0.42857143 | BO18: =SUM(AM18:AS18)/(7*4) -> 0.57142857 | BP18: =SUM(AT18:AX18)/(5*4) -> 0.2 | BQ18: =SUM(AY18:BB18)/(4*4) -> 0.5
A19: RAP69-018 | B19: =IFERROR(VLOOKUP(A19,'01_ข้อมูลร้าน'!$A$2:$B$51,2,FALSE),"") -> อิ่มอุ่น ณ พัทยา | C19: T0 | E19: 2 | F19: 2 | G19: 2 | H19: 3 | I19: 2 | J19: 2 | K19: 2 | L19: 4 | M19: 2 | N19: 1 | O19: 2 | P19: 2 | Q19: 3 | R19: 2 | S19: 3 | T19: 3 | U19: 2 | V19: 2 | W19: 3 | X19: 1 | Y19: 3 | Z19: 2 | AA19: 3 | AB19: 2 | AC19: 2 | AD19: 0 | AE19: 3 | AF19: 2 | AG19: 2 | AH19: 3 | AI19: 3 | AJ19: 3 | AK19: 3 | AL19: 3 | AM19: 3 | AN19: 2 | AO19: 3 | AP19: 2 | AQ19: 1 | AR19: 2 | AS19: 3 | AT19: 2 | AU19: 3 | AV19: 2 | AW19: 2 | AX19: 0 | AY19: 3 | AZ19: 0 | BA19: 0 | BB19: 2 | BC19: =COUNT(E19:BB19)/50 -> 1 | BD19: =SUM(E19:BB19) -> 109 | BE19: =BD19/200 -> 0.545 | BF19: =SUM(E19:K19)/(7*4)*0.12+SUM(L19:R19)/(7*4)*0.15+SUM(S19:X19)/(6*4)*0.1+SUM(Y19:AE19)/(7*4)*0.13+SUM(AF19:AL19)/(7*4)*0.2+SUM(AM19:AS19)/(7*4)*0.18+SUM(AT19:AX19)/(5*4)*0.05+SUM(AY19:BB19)/(4*4)*0.07 -> 0.56092262 | BG19: =COUNTIFS(E19:BB19,">=0",E19:BB19,"<=1") -> 7 | BH19: =IF(BC19=0,"ยังไม่ประเมิน",IF(BF19>=0.8,"ดีมาก",IF(BF19>=0.65,"ดี",IF(BF19>=0.5,"ต้องพัฒนา","เร่งแก้ไข")))) -> ต้องพัฒนา | BI19: =IF(BC19=0,"ยังไม่ประเมิน",INDEX($BJ$1:$BQ$1,1,MATCH(MIN(BJ19:BQ19),BJ19:BQ19,0))) -> มิติ 8 | BJ19: =SUM(E19:K19)/(7*4) -> 0.53571429 | BK19: =SUM(L19:R19)/(7*4) -> 0.57142857 | BL19: =SUM(S19:X19)/(6*4) -> 0.58333333 | BM19: =SUM(Y19:AE19)/(7*4) -> 0.53571429 | BN19: =SUM(AF19:AL19)/(7*4) -> 0.67857143 | BO19: =SUM(AM19:AS19)/(7*4) -> 0.57142857 | BP19: =SUM(AT19:AX19)/(5*4) -> 0.45 | BQ19: =SUM(AY19:BB19)/(4*4) -> 0.3125
A20: RAP69-019 | B20: =IFERROR(VLOOKUP(A20,'01_ข้อมูลร้าน'!$A$2:$B$51,2,FALSE),"") -> ร้านอาหารบ่อทองบุรี | C20: T0 | E20: 4 | F20: 2 | G20: 3 | H20: 1 | I20: 3 | J20: 3 | K20: 2 | L20: 4 | M20: 4 | N20: 4 | O20: 4 | P20: 4 | Q20: 4 | R20: 3 | S20: 3 | T20: 3 | U20: 3 | V20: 2 | W20: 3 | X20: 3 | Y20: 3 | Z20: 3 | AA20: 3 | AB20: 2 | AC20: 3 | AD20: 2 | AE20: 3 | AF20: 1 | AG20: 1 | AH20: 2 | AI20: 4 | AJ20: 4 | AK20: 3 | AL20: 4 | AM20: 4 | AN20: 4 | AO20: 4 | AP20: 4 | AQ20: 4 | AR20: 3 | AS20: 3 | AT20: 3 | AU20: 4 | AV20: 3 | AW20: 3 | AX20: 2 | AY20: 3 | AZ20: 3 | BA20: 3 | BB20: 2 | BC20: =COUNT(E20:BB20)/50 -> 1 | BD20: =SUM(E20:BB20) -> 152 | BE20: =BD20/200 -> 0.76 | BF20: =SUM(E20:K20)/(7*4)*0.12+SUM(L20:R20)/(7*4)*0.15+SUM(S20:X20)/(6*4)*0.1+SUM(Y20:AE20)/(7*4)*0.13+SUM(AF20:AL20)/(7*4)*0.2+SUM(AM20:AS20)/(7*4)*0.18+SUM(AT20:AX20)/(5*4)*0.05+SUM(AY20:BB20)/(4*4)*0.07 -> 0.76931548 | BG20: =COUNTIFS(E20:BB20,">=0",E20:BB20,"<=1") -> 3 | BH20: =IF(BC20=0,"ยังไม่ประเมิน",IF(BF20>=0.8,"ดีมาก",IF(BF20>=0.65,"ดี",IF(BF20>=0.5,"ต้องพัฒนา","เร่งแก้ไข")))) -> ดี | BI20: =IF(BC20=0,"ยังไม่ประเมิน",INDEX($BJ$1:$BQ$1,1,MATCH(MIN(BJ20:BQ20),BJ20:BQ20,0))) -> มิติ 1 | BJ20: =SUM(E20:K20)/(7*4) -> 0.64285714 | BK20: =SUM(L20:R20)/(7*4) -> 0.96428571 | BL20: =SUM(S20:X20)/(6*4) -> 0.70833333 | BM20: =SUM(Y20:AE20)/(7*4) -> 0.67857143 | BN20: =SUM(AF20:AL20)/(7*4) -> 0.67857143 | BO20: =SUM(AM20:AS20)/(7*4) -> 0.92857143 | BP20: =SUM(AT20:AX20)/(5*4) -> 0.75 | BQ20: =SUM(AY20:BB20)/(4*4) -> 0.6875
A21: RAP69-020 | B21: =IFERROR(VLOOKUP(A21,'01_ข้อมูลร้าน'!$A$2:$B$51,2,FALSE),"") -> ผัดไทยคาเฟ่แม่วรรณา | C21: T0 | E21: 3 | F21: 4 | G21: 4 | H21: 2 | I21: 2 | J21: 2 | K21: 2 | L21: 3 | M21: 3 | N21: 2 | O21: 2 | P21: 3 | Q21: 3 | R21: 3 | S21: 4 | T21: 0 | U21: 2 | V21: 2 | W21: 2 | X21: 1 | Y21: 3 | Z21: 2 | AA21: 3 | AB21: 2 | AC21: 1 | AD21: 2 | AE21: 2 | AF21: 0 | AG21: 1 | AH21: 0 | AI21: 3 | AJ21: 3 | AK21: 2 | AL21: 2 | AM21: 3 | AN21: 3 | AO21: 3 | AP21: 2 | AQ21: 2 | AR21: 3 | AS21: 3 | AT21: 3 | AU21: 3 | AV21: 2 | AW21: 0 | AX21: 0 | AY21: 2 | AZ21: 3 | BA21: 3 | BB21: 2 | BC21: =COUNT(E21:BB21)/50 -> 1 | BD21: =SUM(E21:BB21) -> 112 | BE21: =BD21/200 -> 0.56 | BF21: =SUM(E21:K21)/(7*4)*0.12+SUM(L21:R21)/(7*4)*0.15+SUM(S21:X21)/(6*4)*0.1+SUM(Y21:AE21)/(7*4)*0.13+SUM(AF21:AL21)/(7*4)*0.2+SUM(AM21:AS21)/(7*4)*0.18+SUM(AT21:AX21)/(5*4)*0.05+SUM(AY21:BB21)/(4*4)*0.07 -> 0.56315476 | BG21: =COUNTIFS(E21:BB21,">=0",E21:BB21,"<=1") -> 8 | BH21: =IF(BC21=0,"ยังไม่ประเมิน",IF(BF21>=0.8,"ดีมาก",IF(BF21>=0.65,"ดี",IF(BF21>=0.5,"ต้องพัฒนา","เร่งแก้ไข")))) -> ต้องพัฒนา | BI21: =IF(BC21=0,"ยังไม่ประเมิน",INDEX($BJ$1:$BQ$1,1,MATCH(MIN(BJ21:BQ21),BJ21:BQ21,0))) -> มิติ 5 | BJ21: =SUM(E21:K21)/(7*4) -> 0.67857143 | BK21: =SUM(L21:R21)/(7*4) -> 0.67857143 | BL21: =SUM(S21:X21)/(6*4) -> 0.45833333 | BM21: =SUM(Y21:AE21)/(7*4) -> 0.53571429 | BN21: =SUM(AF21:AL21)/(7*4) -> 0.39285714 | BO21: =SUM(AM21:AS21)/(7*4) -> 0.67857143 | BP21: =SUM(AT21:AX21)/(5*4) -> 0.4 | BQ21: =SUM(AY21:BB21)/(4*4) -> 0.625
A22: RAP69-021 | B22: =IFERROR(VLOOKUP(A22,'01_ข้อมูลร้าน'!$A$2:$B$51,2,FALSE),"") -> Recharge Cafa | C22: T0 | E22: 2 | F22: 2 | G22: 2 | H22: 0 | I22: 1 | J22: 2 | K22: 1 | L22: 3 | M22: 3 | N22: 1 | O22: 1 | P22: 2 | Q22: 1 | R22: 2 | S22: 0 | T22: 2 | U22: 2 | V22: 2 | W22: 2 | X22: 1 | Y22: 1 | Z22: 2 | AA22: 2 | AB22: 1 | AC22: 2 | AD22: 2 | AE22: 2 | AF22: 2 | AG22: 1 | AH22: 3 | AI22: 2 | AJ22: 2 | AK22: 2 | AL22: 2 | AM22: 2 | AN22: 2 | AO22: 3 | AP22: 2 | AQ22: 2 | AR22: 3 | AS22: 2 | AT22: 1 | AU22: 1 | AV22: 2 | AW22: 0 | AX22: 0 | AY22: 3 | AZ22: 3 | BA22: 2 | BB22: 1 | BC22: =COUNT(E22:BB22)/50 -> 1 | BD22: =SUM(E22:BB22) -> 87 | BE22: =BD22/200 -> 0.435 | BF22: =SUM(E22:K22)/(7*4)*0.12+SUM(L22:R22)/(7*4)*0.15+SUM(S22:X22)/(6*4)*0.1+SUM(Y22:AE22)/(7*4)*0.13+SUM(AF22:AL22)/(7*4)*0.2+SUM(AM22:AS22)/(7*4)*0.18+SUM(AT22:AX22)/(5*4)*0.05+SUM(AY22:BB22)/(4*4)*0.07 -> 0.45794643 | BG22: =COUNTIFS(E22:BB22,">=0",E22:BB22,"<=1") -> 16 | BH22: =IF(BC22=0,"ยังไม่ประเมิน",IF(BF22>=0.8,"ดีมาก",IF(BF22>=0.65,"ดี",IF(BF22>=0.5,"ต้องพัฒนา","เร่งแก้ไข")))) -> เร่งแก้ไข | BI22: =IF(BC22=0,"ยังไม่ประเมิน",INDEX($BJ$1:$BQ$1,1,MATCH(MIN(BJ22:BQ22),BJ22:BQ22,0))) -> มิติ 7 | BJ22: =SUM(E22:K22)/(7*4) -> 0.35714286 | BK22: =SUM(L22:R22)/(7*4) -> 0.46428571 | BL22: =SUM(S22:X22)/(6*4) -> 0.375 | BM22: =SUM(Y22:AE22)/(7*4) -> 0.42857143 | BN22: =SUM(AF22:AL22)/(7*4) -> 0.5 | BO22: =SUM(AM22:AS22)/(7*4) -> 0.57142857 | BP22: =SUM(AT22:AX22)/(5*4) -> 0.2 | BQ22: =SUM(AY22:BB22)/(4*4) -> 0.5625
A23: RAP69-022 | B23: =IFERROR(VLOOKUP(A23,'01_ข้อมูลร้าน'!$A$2:$B$51,2,FALSE),"") -> หมึกสดริมเล | C23: T0 | E23: 4 | F23: 4 | G23: 3 | H23: 3 | I23: 3 | J23: 4 | K23: 4 | L23: 2 | M23: 3 | N23: 4 | O23: 4 | P23: 4 | Q23: 4 | R23: 2 | S23: 4 | T23: 4 | U23: 4 | V23: 4 | W23: 4 | X23: 4 | Y23: 4 | Z23: 4 | AA23: 4 | AB23: 4 | AC23: 4 | AD23: 4 | AE23: 4 | AF23: 4 | AG23: 4 | AH23: 4 | AI23: 4 | AJ23: 4 | AK23: 4 | AL23: 4 | AM23: 4 | AN23: 4 | AO23: 3 | AP23: 4 | AQ23: 3 | AR23: 4 | AS23: 4 | AT23: 4 | AU23: 4 | AV23: 3 | AW23: 1 | AX23: 1 | AY23: 4 | AZ23: 4 | BA23: 4 | BB23: 3 | BC23: =COUNT(E23:BB23)/50 -> 1 | BD23: =SUM(E23:BB23) -> 182 | BE23: =BD23/200 -> 0.91 | BF23: =SUM(E23:K23)/(7*4)*0.12+SUM(L23:R23)/(7*4)*0.15+SUM(S23:X23)/(6*4)*0.1+SUM(Y23:AE23)/(7*4)*0.13+SUM(AF23:AL23)/(7*4)*0.2+SUM(AM23:AS23)/(7*4)*0.18+SUM(AT23:AX23)/(5*4)*0.05+SUM(AY23:BB23)/(4*4)*0.07 -> 0.925625 | BG23: =COUNTIFS(E23:BB23,">=0",E23:BB23,"<=1") -> 2 | BH23: =IF(BC23=0,"ยังไม่ประเมิน",IF(BF23>=0.8,"ดีมาก",IF(BF23>=0.65,"ดี",IF(BF23>=0.5,"ต้องพัฒนา","เร่งแก้ไข")))) -> ดีมาก | BI23: =IF(BC23=0,"ยังไม่ประเมิน",INDEX($BJ$1:$BQ$1,1,MATCH(MIN(BJ23:BQ23),BJ23:BQ23,0))) -> มิติ 7 | BJ23: =SUM(E23:K23)/(7*4) -> 0.89285714 | BK23: =SUM(L23:R23)/(7*4) -> 0.82142857 | BL23: =SUM(S23:X23)/(6*4) -> 1 | BM23: =SUM(Y23:AE23)/(7*4) -> 1 | BN23: =SUM(AF23:AL23)/(7*4) -> 1 | BO23: =SUM(AM23:AS23)/(7*4) -> 0.92857143 | BP23: =SUM(AT23:AX23)/(5*4) -> 0.65 | BQ23: =SUM(AY23:BB23)/(4*4) -> 0.9375
